Workbook

Sheet HPP MALL
A1: Nama Produk MALL | B1: HARGA NASIONAL | C1: HARGA NASIONAL (PCS) | D1: HARGA NASIONAL (PCS) | E1: ECOM (PCS) | S1: ECOM (PCS/PACK) / BOX | AG1: ECOM CTN
E2: min (PCS) | F2: ADM MARKETPLACE (INC. PPN) | J2: Biaya | K2: BIAYA OPS | L2: HPP | M2: MARGIN ECOM | N2: PROFIT | O2: HARGA JUAL (PCS) | Q2: Harga Jual /pcs | S2: PACK (PCS) | T2: ADM MARKETPLACE (INC. PPN) | X2: Biaya | Y2: BIAYA OPS | Z2: HPP | AA2: MARGIN | AB2: PROFIT | AC2: HARGA JUAL (PACK) | AE2: HARGA JUAL SATUAN | AG2: (PCS) | AH2: ADM MARKETPLACE (INC. PPN) | AL2: Biaya | AM2: BIAYA OPS | AN2: HPP | AO2: MARGIN 2.5% | AP2: PROFIT | AQ2: HARGA JUAL (PCS) | AS2: HARGA JUAL SATUAN) | AT2: CTN (PCS) | AU2: ADM MARKETPLACE (INC. PPN) | AV2: Biaya | AW2: BIAYA OPS | AX2: HPP | AY2: MARGIN CMS | AZ2: PROFIT | BA2: HARGA JUAL (PCS) | BC2: HARGA JUAL (BOX)
C3: (INC PPN) | D3: (EXC PPN) | F3: 0.118 | G3: 0.08 | H3: 0.045 | I3: 0.018 | J3: 1250 | K3: 0.08 | L3: (EXC PPN) | M3: 0.025 | O3: (EXC PPN) | P3: (INCL PPN) | T3: 0.117 | U3: 0.08 | V3: 0.045 | W3: 0.018 | Y3: 0.08 | Z3: (EXC PPN) | AC3: (EXC PPN) | AD3: (INC PPN) | AH3: 0.117 | AI3: 0.08 | AJ3: 0.045 | AK3: 0.018 | AM3: 0.03 | AN3: (EXC PPN) | AQ3: (EXC PPN) | AR3: (INC PPN) | AU3: 0.17 | AW3: 0.04 | AX3: (EXC PPN) | BA3: (EXC PPN) | BB3: (INC PPN)
A4: Per Pcs | C4: 0.82 | D4: 1.11 | O4: 1.11
A5: CROCKIE ORIGINAL | B5: 3350 | C5: =B5*$C$4 -> 2747 | D5: =C5/$D$4 -> 2474.7748 | E5: 4 | F5: =P5*$F$3 -> 2301 | G5: =P5*$G$3 -> 1560 | H5: =P5*$H$3 -> 877.5 | I5: =P5*$I$3 -> 351 | J5: 1250 | K5: =C5*$K$3*E5 -> 879.04 | L5: =(D5*E5)+F5+G5+H5+I5+J5+K5 -> 17117.639 | M5: =N5/O5 -> 0.025611313 | N5: =O5-L5 -> 449.92847 | O5: =P5/$O$4 -> 17567.568 | P5: 19500 | Q5: =P5/E5 -> 4875 | S5: 50 | T5: =AD5*$T$3 -> 25740 | U5: =AD5*$U$3 -> 17600 | V5: =AD5*$V$3 -> 9900 | W5: =AD5*$W$3 -> 3960 | X5: 1250 | Y5: =C5*$Y$3*S5 -> 10988 | Z5: =(D5*S5)+T5+U5+V5+W5+X5+Y5 -> 193176.74 | AA5: =AB5/AC5 -> 0.025335545 | AB5: =AC5-Z5 -> 5021.4595 | AC5: =AD5/$O$4 -> 198198.2 | AD5: 220000 | AE5: =AD5/S5 -> 4400 | AG5: 500 | AH5: =AR5*$T$3 -> 239850 | AI5: =AR5*$U$3 -> 164000 | AJ5: =AR5*$V$3 -> 92250 | AK5: =AR5*$W$3 -> 36900 | AL5: 1250 | AM5: =C5*$AM$3*AG5 -> 41205 | AN5: =(D5*AG5)+AH5+AI5+AJ5+AK5+AL5+AM5 -> 1812842.4 | AO5: =AP5/AQ5 -> 0.018412171 | AP5: =AQ5-AN5 -> 34004.459 | AQ5: =AR5/$O$4 -> 1846846.8 | AR5: 2050000 | AS5: =AR5/AG5 -> 4100
A6: CROCKIE MAGNET SUPER | B6: 3500 | C6: =B6*$C$4 -> 2870 | D6: =C6/$D$4 -> 2585.5856 | E6: 4 | F6: =P6*$F$3 -> 2596 | G6: =P6*$G$3 -> 1760 | H6: =P6*$H$3 -> 990 | I6: =P6*$I$3 -> 396 | J6: 1250 | K6: =C6*$K$3*E6 -> 918.4 | L6: =(D6*E6)+F6+G6+H6+I6+J6+K6 -> 18252.742 | M6: =N6/O6 -> 0.079066182 | N6: =O6-L6 -> 1567.0775 | O6: =P6/$O$4 -> 19819.82 | P6: 22000 | Q6: =P6/E6 -> 5500 | S6: 50 | T6: =AD6*$T$3 -> 26910 | U6: =AD6*$U$3 -> 18400 | V6: =AD6*$V$3 -> 10350 | W6: =AD6*$W$3 -> 4140 | X6: 1250 | Y6: =C6*$Y$3*S6 -> 11480 | Z6: =(D6*S6)+T6+U6+V6+W6+X6+Y6 -> 201809.28 | AA6: =AB6/AC6 -> 0.02605087 | AB6: =AC6-Z6 -> 5397.9279 | AC6: =AD6/$O$4 -> 207207.21 | AD6: 230000 | AE6: =AD6/S6 -> 4600 | AG6: 500 | AH6: =AR6*$AH$3 -> 251550 | AI6: =AR6*$AI$3 -> 172000 | AJ6: =AR6*$AJ$3 -> 96750 | AK6: =AR6*$AK$3 -> 38700 | AL6: 1250 | AM6: =C6*$AM$3*AG6 -> 43050 | AN6: =(D6*AG6)+AH6+AI6+AJ6+AK6+AL6+AM6 -> 1896092.8 | AO6: =AP6/AQ6 -> 0.021086977 | AP6: =AQ6-AN6 -> 40844.144 | AQ6: =AR6/$O$4 -> 1936936.9 | AR6: 2150000 | AS6: =AR6/AG6 -> 4300
A7: CROCKIE BARA TURBO | B7: 4100 | C7: =B7*$C$4 -> 3362 | D7: =C7/$D$4 -> 3028.8288 | E7: 4 | F7: =P7*$F$3 -> 2773 | G7: =P7*$G$3 -> 1880 | H7: =P7*$H$3 -> 1057.5 | I7: =P7*$I$3 -> 423 | J7: 1250 | K7: =C7*$K$3*E7 -> 1075.84 | L7: =(D7*E7)+F7+G7+H7+I7+J7+K7 -> 20574.655 | M7: =N7/O7 -> 0.028175855 | N7: =O7-L7 -> 596.51586 | O7: =P7/$O$4 -> 21171.171 | P7: 23500 | Q7: =P7/E7 -> 5875 | S7: 25 | T7: =AD7*$T$3 -> 15838.875 | U7: =AD7*$U$3 -> 10830 | V7: =AD7*$V$3 -> 6091.875 | W7: =AD7*$W$3 -> 2436.75 | X7: 1250 | Y7: =C7*$Y$3*S7 -> 6724 | Z7: =(D7*S7)+T7+U7+V7+W7+X7+Y7 -> 118892.22 | AA7: =AB7/AC7 -> 0.025149658 | AB7: =AC7-Z7 -> 3067.2387 | AC7: =AD7/$O$4 -> 121959.46 | AD7: 135375 | AE7: =AD7/S7 -> 5415 | AG7: 500 | AH7: =AR7*$AH$3 -> 0 | AI7: =AR7*$AI$3 -> 0 | AJ7: =AR7*$AJ$3 -> 0 | AK7: =AR7*$AK$3 -> 0 | AL7: 1250 | AM7: =C7*$AM$3*AG7 -> 50430 | AN7: =(D7*AG7)+AH7+AI7+AJ7+AK7+AL7+AM7 -> 1566094.4 | AO7: =AP7/AQ7 -> #DIV/0! | AP7: =AQ7-AN7 -> -1566094.4 | AQ7: =AR7/$O$4 -> 0 | AS7: =AR7/AG7 -> 0
A8: CROCKIE SUPER JET | B8: 25000 | C8: =B8*$C$4 -> 20500 | D8: =C8/$D$4 -> 18468.468 | E8: 1 | F8: =P8*$F$3 -> 4130 | G8: =P8*$G$3 -> 2800 | H8: =P8*$H$3 -> 1575 | I8: =P8*$I$3 -> 630 | J8: 1250 | K8: =C8*$K$3*E8 -> 1640 | L8: =(D8*E8)+F8+G8+H8+I8+J8+K8 -> 30493.468 | M8: =N8/O8 -> 0.032921429 | N8: =O8-L8 -> 1038.0631 | O8: =P8/$O$4 -> 31531.532 | P8: 35000 | Q8: =P8/E8 -> 35000 | S8: 4 | T8: =AD8*$T$3 -> 15678 | U8: =AD8*$U$3 -> 10720 | V8: =AD8*$V$3 -> 6030 | W8: =AD8*$W$3 -> 2412 | X8: 1250 | Y8: =C8*$Y$3*S8 -> 6560 | Z8: =(D8*S8)+T8+U8+V8+W8+X8+Y8 -> 116523.87 | AA8: =AB8/AC8 -> 0.034764925 | AB8: =AC8-Z8 -> 4196.8468 | AC8: =AD8/$O$4 -> 120720.72 | AD8: 134000 | AE8: =AD8/S8 -> 33500 | AG8: 100 | AH8: =AR8*$AH$3 -> 0 | AI8: =AR8*$AI$3 -> 0 | AJ8: =AR8*$AJ$3 -> 0 | AK8: =AR8*$AK$3 -> 0 | AL8: 1250 | AM8: =C8*$AM$3*AG8 -> 61500 | AN8: =(D8*AG8)+AH8+AI8+AJ8+AK8+AL8+AM8 -> 1909596.8 | AO8: =AP8/AQ8 -> #DIV/0! | AP8: =AQ8-AN8 -> -1909596.8 | AQ8: =AR8/$O$4 -> 0 | AS8: =AR8/AG8 -> 0
A9: CROCKIE IDEA | B9: 10000 | C9: =B9*$C$4 -> 8200 | D9: =C9/$D$4 -> 7387.3874 | E9: 1 | F9: =P9*$F$3 -> 1810.71 | G9: =P9*$G$3 -> 1227.6 | H9: =P9*$H$3 -> 690.525 | I9: =P9*$I$3 -> 276.21 | J9: 1250 | K9: =C9*$K$3*E9 -> 656 | L9: =(D9*E9)+F9+G9+H9+I9+J9+K9 -> 13298.432 | M9: =N9/O9 -> 0.038041059 | N9: =O9-L9 -> 525.89194 | O9: =P9/$O$4 -> 13824.324 | P9: 15345 | Q9: =P9/E9 -> 15345 | S9: 16 | T9: =AD9*$T$3 -> 24687 | U9: =AD9*$U$3 -> 16880 | V9: =AD9*$V$3 -> 9495 | W9: =AD9*$W$3 -> 3798 | X9: 1250 | Y9: =C9*$Y$3*S9 -> 10496 | Z9: =(D9*S9)+T9+U9+V9+W9+X9+Y9 -> 184804.2 | AA9: =AB9/AC9 -> 0.027807299 | AB9: =AC9-Z9 -> 5285.8919 | AC9: =AD9/$O$4 -> 190090.09 | AD9: 211000 | AE9: =AD9/S9 -> 13187.5 | AH9: =AR9*$AH$3 -> 0 | AI9: =AR9*$AI$3 -> 0 | AJ9: =AR9*$AJ$3 -> 0 | AK9: =AR9*$AK$3 -> 0 | AL9: 1250 | AM9: =C9*$AM$3*AG9 -> 0 | AN9: =(D9*AG9)+AH9+AI9+AJ9+AK9+AL9+AM9 -> 1250 | AO9: =AP9/AQ9 -> #DIV/0! | AP9: =AQ9-AN9 -> -1250 | AQ9: =AR9/$O$4 -> 0 | AS9: =AR9/AG9 -> #DIV/0!
A10: CROCKIE FLEXIE | B10: 15000 | C10: =B10*$C$4 -> 12300 | D10: =C10/$D$4 -> 11081.081 | E10: 1 | F10: =P10*$F$3 -> 2596 | G10: =P10*$G$3 -> 1760 | H10: =P10*$H$3 -> 990 | I10: =P10*$I$3 -> 396 | J10: 1250 | K10: =C10*$K$3*E10 -> 984 | L10: =(D10*E10)+F10+G10+H10+I10+J10+K10 -> 19057.081 | M10: =N10/O10 -> 0.038483636 | N10: =O10-L10 -> 762.73874 | O10: =P10/$O$4 -> 19819.82 | P10: 22000 | Q10: =P10/E10 -> 22000 | S10: 4 | T10: =AD10*$T$3 -> 9711 | U10: =AD10*$U$3 -> 6640 | V10: =AD10*$V$3 -> 3735 | W10: =AD10*$W$3 -> 1494 | X10: 1250 | Y10: =C10*$Y$3*S10 -> 3936 | Z10: =(D10*S10)+T10+U10+V10+W10+X10+Y10 -> 71090.324 | AA10: =AB10/AC10 -> 0.049273976 | AB10: =AC10-Z10 -> 3684.4504 | AC10: =AD10/$O$4 -> 74774.775 | AD10: 83000 | AE10: =AD10/S10 -> 20750 | AH10: =AR10*$AH$3 -> 0 | AI10: =AR10*$AI$3 -> 0 | AJ10: =AR10*$AJ$3 -> 0 | AK10: =AR10*$AK$3 -> 0 | AL10: 1250 | AM10: =C10*$AM$3*AG10 -> 0 | AN10: =(D10*AG10)+AH10+AI10+AJ10+AK10+AL10+AM10 -> 1250 | AO10: =AP10/AQ10 -> #DIV/0! | AP10: =AQ10-AN10 -> -1250 | AQ10: =AR10/$O$4 -> 0 | AS10: =AR10/AG10 -> #DIV/0!
A11: CROCKIE FLEXIE WINDPROOF | B11: 18000 | C11: =B11*$C$4 -> 14760 | D11: =C11/$D$4 -> 13297.297 | E11: 1 | F11: =P11*$F$3 -> 3026.7 | G11: =P11*$G$3 -> 2052 | H11: =P11*$H$3 -> 1154.25 | I11: =P11*$I$3 -> 461.7 | J11: 1250 | K11: =C11*$K$3*E11 -> 1180.8 | L11: =(D11*E11)+F11+G11+H11+I11+J11+K11 -> 22422.747 | M11: =N11/O11 -> 0.029658889 | N11: =O11-L11 -> 685.36081 | O11: =P11/$O$4 -> 23108.108 | P11: 25650 | Q11: =P11/E11 -> 25650 | T11: =AD11*$T$3 -> 0 | U11: =AD11*$U$3 -> 0 | V11: =AD11*$V$3 -> 0 | W11: =AD11*$W$3 -> 0 | X11: 1250 | Y11: =C11*$Y$3*S11 -> 0 | Z11: =(D11*S11)+T11+U11+V11+W11+X11+Y11 -> 1250 | AA11: =AB11/AC11 -> #DIV/0! | AB11: =AC11-Z11 -> -1250 | AC11: =AD11/$O$4 -> 0 | AE11: =AD11/S11 -> #DIV/0! | AH11: =AR11*$AH$3 -> 0 | AI11: =AR11*$AI$3 -> 0 | AJ11: =AR11*$AJ$3 -> 0 | AK11: =AR11*$AK$3 -> 0 | AL11: 1250 | AM11: =C11*$AM$3*AG11 -> 0 | AN11: =(D11*AG11)+AH11+AI11+AJ11+AK11+AL11+AM11 -> 1250 | AO11: =AP11/AQ11 -> #DIV/0! | AP11: =AQ11-AN11 -> -1250 | AQ11: =AR11/$O$4 -> 0 | AS11: =AR11/AG11 -> #DIV/0!
A12: CROCKIE POWER JET | B12: 73000 | C12: =B12*$C$4 -> 59860 | D12: =C12/$D$4 -> 53927.928 | E12: 1 | F12: =P12*$F$3 -> 11446 | G12: =P12*$G$3 -> 7760 | H12: =P12*$H$3 -> 4365 | I12: =P12*$I$3 -> 1746 | J12: 1250 | K12: =C12*$K$3*E12 -> 4788.8 | L12: =(D12*E12)+F12+G12+H12+I12+J12+K12 -> 85283.728 | M12: =N12/O12 -> 0.024072804 | N12: =O12-L12 -> 2103.6595 | O12: =P12/$O$4 -> 87387.387 | P12: 97000 | Q12: =P12/E12 -> 97000 | T12: =AD12*$T$3 -> 0 | U12: =AD12*$U$3 -> 0 | V12: =AD12*$V$3 -> 0 | W12: =AD12*$W$3 -> 0 | X12: 1250 | Y12: =C12*$Y$3*S12 -> 0 | Z12: =(D12*S12)+T12+U12+V12+W12+X12+Y12 -> 1250 | AA12: =AB12/AC12 -> #DIV/0! | AB12: =AC12-Z12 -> -1250 | AC12: =AD12/$O$4 -> 0 | AE12: =AD12/S12 -> #DIV/0! | AH12: =AR12*$AH$3 -> 0 | AI12: =AR12*$AI$3 -> 0 | AJ12: =AR12*$AJ$3 -> 0 | AK12: =AR12*$AK$3 -> 0 | AL12: 1250 | AM12: =C12*$AM$3*AG12 -> 0 | AN12: =(D12*AG12)+AH12+AI12+AJ12+AK12+AL12+AM12 -> 1250 | AO12: =AP12/AQ12 -> #DIV/0! | AP12: =AQ12-AN12 -> -1250 | AQ12: =AR12/$O$4 -> 0 | AS12: =AR12/AG12 -> #DIV/0!
A13: CROCKIE GAS BUTANE | B13: 5900 | C13: =B13*$C$4 -> 4838 | D13: =C13/$D$4 -> 4358.5586 | E13: 1 | F13: =P13*$F$3 -> 1239 | G13: =P13*$G$3 -> 840 | H13: =P13*$H$3 -> 472.5 | I13: =P13*$I$3 -> 189 | J13: 1250 | K13: =C13*$K$3*E13 -> 387.04 | L13: =(D13*E13)+F13+G13+H13+I13+J13+K13 -> 8736.0986 | M13: =N13/O13 -> 0.076469581 | N13: =O13-L13 -> 723.3609 | O13: =P13/$O$4 -> 9459.4595 | P13: 10500 | Q13: =P13/E13 -> 10500 | S13: 25 | T13: =AD13*$T$3 -> 22698 | U13: =AD13*$U$3 -> 15520 | V13: =AD13*$V$3 -> 8730 | W13: =AD13*$W$3 -> 3492 | X13: 1250 | Y13: =C13*$Y$3*S13 -> 9676 | Z13: =(D13*S13)+T13+U13+V13+W13+X13+Y13 -> 170329.96 | AA13: =AB13/AC13 -> 0.025431649 | AB13: =AC13-Z13 -> 4444.8108 | AC13: =AD13/$O$4 -> 174774.77 | AD13: 194000 | AE13: =AD13/S13 -> 7760 | AG13: 300 | AH13: =AR13*$AH$3 -> 258570 | AI13: =AR13*$AI$3 -> 176800 | AJ13: =AR13*$AJ$3 -> 99450 | AK13: =AR13*$AK$3 -> 39780 | AL13: 1250 | AM13: =C13*$AM$3*AG13 -> 43542 | AN13: =(D13*AG13)+AH13+AI13+AJ13+AK13+AL13+AM13 -> 1926959.6 | AO13: =AP13/AQ13 -> 0.032160579 | AP13: =AQ13-AN13 -> 64031.423 | AQ13: =AR13/$O$4 -> 1990991 | AR13: 2210000 | AS13: =AR13/AG13 -> 7366.6667
A14: CROCKIE MAGNET SUPER PLAIN WHITE | B14: 3500 | C14: =B14*$C$4 -> 2870 | D14: =C14/$D$4 -> 2585.5856 | E14: 5 | F14: =P14*$F$3 -> 3068 | G14: =P14*$G$3 -> 2080 | H14: =P14*$H$3 -> 1170 | I14: =P14*$I$3 -> 468 | J14: 1250 | K14: =C14*$K$3*E14 -> 1148 | L14: =(D14*E14)+F14+G14+H14+I14+J14+K14 -> 22111.928 | M14: =N14/O14 -> 0.055990769 | N14: =O14-L14 -> 1311.4955 | O14: =P14/$O$4 -> 23423.423 | P14: 26000 | Q14: =P14/E14 -> 5200 | T14: =AD14*$T$3 -> 0 | U14: =AD14*$U$3 -> 0 | V14: =AD14*$V$3 -> 0 | W14: =AD14*$W$3 -> 0 | X14: 1250 | Y14: =C14*$Y$3*S14 -> 0 | Z14: =(D14*S14)+T14+U14+V14+W14+X14+Y14 -> 1250 | AA14: =AB14/AC14 -> #DIV/0! | AB14: =AC14-Z14 -> -1250 | AC14: =AD14/$O$4 -> 0 | AE14: =AD14/S14 -> #DIV/0! | AG14: 500 | AH14: =AR14*$AH$3 -> 243418.5 | AI14: =AR14*$AI$3 -> 166440 | AJ14: =AR14*$AJ$3 -> 93622.5 | AK14: =AR14*$AK$3 -> 37449 | AL14: 1250 | AM14: =C14*$AM$3*AG14 -> 43050 | AN14: =(D14*AG14)+AH14+AI14+AJ14+AK14+AL14+AM14 -> 1878022.8 | AO14: =AP14/AQ14 -> -0.0010782478 | AP14: =AQ14-AN14 -> -2022.7928 | AQ14: 1876000 | AR14: 2080500 | AS14: =AR14/AG14 -> 4161
A15: CROCKIE MAGNET SUPER PLAIN BLACK | B15: 3500 | C15: =B15*$C$4 -> 2870 | D15: =C15/$D$4 -> 2585.5856 | E15: 3 | F15: =P15*$F$3 -> 1947 | G15: =P15*$G$3 -> 1320 | H15: =P15*$H$3 -> 742.5 | I15: =P15*$I$3 -> 297 | J15: 1250 | K15: =C15*$K$3*E15 -> 688.8 | L15: =(D15*E15)+F15+G15+H15+I15+J15+K15 -> 14002.057 | M15: =N15/O15 -> 0.058043455 | N15: =O15-L15 -> 862.80811 | O15: =P15/$O$4 -> 14864.865 | P15: 16500 | Q15: =P15/E15 -> 5500 | T15: =AD15*$T$3 -> 0 | U15: =AD15*$U$3 -> 0 | V15: =AD15*$V$3 -> 0 | W15: =AD15*$W$3 -> 0 | X15: 1250 | Y15: =C15*$Y$3*S15 -> 0 | Z15: =(D15*S15)+T15+U15+V15+W15+X15+Y15 -> 1250 | AA15: =AB15/AC15 -> #DIV/0! | AB15: =AC15-Z15 -> -1250 | AC15: =AD15/$O$4 -> 0 | AE15: =AD15/S15 -> #DIV/0! | AG15: 500 | AH15: =AR15*$AH$3 -> 255645 | AI15: =AR15*$AI$3 -> 174800 | AJ15: =AR15*$AJ$3 -> 98325 | AK15: =AR15*$AK$3 -> 39330 | AL15: 1250 | AM15: =C15*$AM$3*AG15 -> 43050 | AN15: =(D15*AG15)+AH15+AI15+AJ15+AK15+AL15+AM15 -> 1905192.8 | AO15: =AP15/AQ15 -> 0.032144622 | AP15: =AQ15-AN15 -> 63275.676 | AQ15: =AR15/$O$4 -> 1968468.5 | AR15: 2185000 | AS15: =AR15/AG15 -> 4370
A16: CROCKIE MAGNET CUSTOM PRINT UV | B16: =B15+2000 -> 5500 | C16: =B16*$C$4 -> 4510 | D16: =C16/$D$4 -> 4063.0631 | E16: 3 | F16: =P16*$F$3 -> 3221.4 | G16: =P16*$G$3 -> 2184 | H16: =P16*$H$3 -> 1228.5 | I16: =P16*$I$3 -> 491.4 | J16: 1250 | K16: =C16*$K$3*E16 -> 1082.4 | L16: =(D16*E16)+F16+G16+H16+I16+J16+K16 -> 21646.889 | M16: =N16/O16 -> 0.11985176 | N16: =O16-L16 -> 2947.7054 | O16: =P16/$O$4 -> 24594.595 | P16: 27300 | Q16: =P16/E16 -> 9100 | S16: 50 | T16: =AD16*$T$3 -> 0 | U16: =AD16*$U$3 -> 0 | V16: =AD16*$V$3 -> 0 | W16: =AD16*$W$3 -> 0 | X16: 1250 | Y16: =C16*$Y$3*S16 -> 18040 | Z16: =(D16*S16)+T16+U16+V16+W16+X16+Y16 -> 222443.15 | AA16: =AB16/AC16 -> #DIV/0! | AB16: =AC16-Z16 -> -222443.15 | AC16: =AD16/$O$4 -> 0 | AE16: =AD16/S16 -> 0 | AG16: 500 | AH16: =AR16*$AH$3 -> 0 | AI16: =AR16*$AI$3 -> 0 | AJ16: =AR16*$AJ$3 -> 0 | AK16: =AR16*$AK$3 -> 0 | AL16: 1250 | AM16: =C16*$AM$3*AG16 -> 67650 | AN16: =(D16*AG16)+AH16+AI16+AJ16+AK16+AL16+AM16 -> 2100431.5 | AO16: =AP16/AQ16 -> #DIV/0! | AP16: =AQ16-AN16 -> -2100431.5 | AQ16: =AR16/$O$4 -> 0 | AS16: =AR16/AG16 -> 0
A17: CROCKIE SERI FLAG | B17: =B5+500 -> 3850 | C17: =B17*$C$4 -> 3157 | D17: =C17/$D$4 -> 2844.1441 | E17: 5 | F17: =P17*$F$3 -> 3304 | G17: =P17*$G$3 -> 2240 | H17: =P17*$H$3 -> 1260 | I17: =P17*$I$3 -> 504 | J17: 1250 | K17: =C17*$K$3*E17 -> 1262.8 | L17: =(D17*E17)+F17+G17+H17+I17+J17+K17 -> 24041.521 | M17: =N17/O17 -> 0.046925429 | N17: =O17-L17 -> 1183.7045 | O17: =P17/$O$4 -> 25225.225 | P17: 28000 | Q17: =P17/E17 -> 5600 | S17: 50 | T17: =AD17*$T$3 -> 29536.65 | U17: =AD17*$U$3 -> 20196 | V17: =AD17*$V$3 -> 11360.25 | W17: =AD17*$W$3 -> 4544.1 | X17: 1250 | Y17: =C17*$Y$3*S17 -> 12628 | Z17: =(D17*S17)+T17+U17+V17+W17+X17+Y17 -> 221722.21 | AA17: =AB17/AC17 -> 0.025107348 | AB17: =AC17-Z17 -> 5710.2252 | AC17: =AD17/$O$4 -> 227432.43 | AD17: 252450 | AE17: =AD17/S17 -> 5049 | AG17: 500 | AH17: =AR17*$AH$3 -> 0 | AI17: =AR17*$AI$3 -> 0 | AJ17: =AR17*$AJ$3 -> 0 | AK17: =AR17*$AK$3 -> 0 | AL17: 1250 | AM17: =C17*$AM$3*AG17 -> 47355 | AN17: =(D17*AG17)+AH17+AI17+AJ17+AK17+AL17+AM17 -> 1470677.1 | AO17: =AP17/AQ17 -> #DIV/0! | AP17: =AQ17-AN17 -> -1470677.1 | AQ17: =AR17/$O$4 -> 0 | AS17: =AR17/AG17 -> 0
A18: CROCKIE SERIES | B18: =B5+1000 -> 4350 | C18: =B18*$C$4 -> 3567 | D18: =C18/$D$4 -> 3213.5135 | E18: 5 | F18: =P18*$F$3 -> 4649.2 | G18: =P18*$G$3 -> 3152 | H18: =P18*$H$3 -> 1773 | I18: =P18*$I$3 -> 709.2 | J18: 1250 | K18: =C18*$K$3*E18 -> 1426.8 | L18: =(D18*E18)+F18+G18+H18+I18+J18+K18 -> 29027.768 | M18: =N18/O18 -> 0.18221264 | N18: =O18-L18 -> 6467.7279 | O18: =P18/$O$4 -> 35495.495 | P18: 39400 | Q18: =P18/E18 -> 7880 | S18: 50 | T18: =AD18*$T$3 -> 33462 | U18: =AD18*$U$3 -> 22880 | V18: =AD18*$V$3 -> 12870 | W18: =AD18*$W$3 -> 5148 | X18: 1250 | Y18: =C18*$Y$3*S18 -> 14268 | Z18: =(D18*S18)+T18+U18+V18+W18+X18+Y18 -> 250553.68 | AA18: =AB18/AC18 -> 0.027571399 | AB18: =AC18-Z18 -> 7103.982 | AC18: =AD18/$O$4 -> 257657.66 | AD18: 286000 | AE18: =AD18/S18 -> 5720 | AG18: 500 | AH18: =AR18*$AH$3 -> 0 | AI18: =AR18*$AI$3 -> 0 | AJ18: =AR18*$AJ$3 -> 0 | AK18: =AR18*$AK$3 -> 0 | AL18: 1250 | AM18: =C18*$AM$3*AG18 -> 53505 | AN18: =(D18*AG18)+AH18+AI18+AJ18+AK18+AL18+AM18 -> 1661511.8 | AO18: =AP18/AQ18 -> #DIV/0! | AP18: =AQ18-AN18 -> -1661511.8 | AQ18: =AR18/$O$4 -> 0 | AS18: =AR18/AG18 -> 0
A19: CROCKIE JETFLIP | B19: 49000 | C19: =B19*$C$4 -> 40180 | D19: =C19/$D$4 -> 36198.198 | E19: 1 | F19: =P19*$F$3 -> 7906 | G19: =P19*$G$3 -> 5360 | H19: =P19*$H$3 -> 3015 | I19: =P19*$I$3 -> 1206 | J19: 1250 | K19: =C19*$K$3*E19 -> 3214.4 | L19: =(D19*E19)+F19+G19+H19+I19+J19+K19 -> 58149.598 | M19: =N19/O19 -> 0.03662606 | N19: =O19-L19 -> 2210.7622 | O19: =P19/$O$4 -> 60360.36 | P19: 67000 | Q19: =P19/E19 -> 67000 | T19: =AD19*$T$3 -> 0 | U19: =AD19*$U$3 -> 0 | V19: =AD19*$V$3 -> 0 | W19: =AD19*$W$3 -> 0 | X19: 1250 | Y19: =C19*$Y$3*S19 -> 0 | Z19: =(D19*S19)+T19+U19+V19+W19+X19+Y19 -> 1250 | AA19: =AB19/AC19 -> #DIV/0! | AB19: =AC19-Z19 -> -1250 | AC19: =AD19/$O$4 -> 0 | AE19: =AD19/S19 -> #DIV/0! | AH19: =AR19*$AH$3 -> 0 | AI19: =AR19*$AI$3 -> 0 | AJ19: =AR19*$AJ$3 -> 0 | AK19: =AR19*$AK$3 -> 0 | AL19: 1250 | AM19: =C19*$AM$3*AG19 -> 0 | AN19: =(D19*AG19)+AH19+AI19+AJ19+AK19+AL19+AM19 -> 1250 | AO19: =AP19/AQ19 -> #DIV/0! | AP19: =AQ19-AN19 -> -1250 | AQ19: =AR19/$O$4 -> 0 | AS19: =AR19/AG19 -> #DIV/0!
A20: CROCKIE JETFLIP + CUSTOM | B20: =B19+2000 -> 51000 | C20: =B20*$C$4 -> 41820 | D20: =C20/$D$4 -> 37675.676 | E20: 1 | F20: =P20*$F$3 -> 8024 | G20: =P20*$G$3 -> 5440 | H20: =P20*$H$3 -> 3060 | I20: =P20*$I$3 -> 1224 | J20: 1250 | K20: =C20*$K$3*E20 -> 3345.6 | L20: =(D20*E20)+F20+G20+H20+I20+J20+K20 -> 60019.276 | M20: =N20/O20 -> 0.020273588 | N20: =O20-L20 -> 1241.9856 | O20: =P20/$O$4 -> 61261.261 | P20: 68000 | Q20: =Q19-16290 -> 50710
A21: PAKET BUNDLING CROCKIE | AH21: - | AM21: - | AN21: - | AO21: #DIV/0! | AP21: - | AQ21: - | AU21: - | AW21: - | AX21: - | AY21: #DIV/0! | AZ21: - | BA21: -
A22: C. BARA T. 5PCS + GAS B. 1PCS | B22: =B7*5+B13 -> 26400 | C22: =B22*$C$4 -> 21648 | D22: =C22/$D$4 -> 19502.703 | E22: 1 | F22: =P22*$F$3 -> 4248 | G22: =P22*$G$3 -> 2880 | H22: =P22*$H$3 -> 1620 | I22: =P22*$I$3 -> 648 | J22: 1250 | K22: =C22*$K$3*E22 -> 1731.84 | L22: =(D22*E22)+F22+G22+H22+I22+J22+K22 -> 31880.543 | M22: =N22/O22 -> 0.0170166 | N22: =O22-L22 -> 551.88973 | O22: =P22/$O$4 -> 32432.432 | P22: 36000 | Q22: =P22/E22 -> 36000 | T22: =AD22*$T$3 -> 0 | U22: =AD22*$U$3 -> 0 | V22: =AD22*$V$3 -> 0 | W22: =AD22*$W$3 -> 0 | X22: 1250 | Y22: =C22*$Y$3*S22 -> 0 | Z22: =(D22*S22)+T22+U22+V22+W22+X22+Y22 -> 1250 | AA22: =AB22/AC22 -> #DIV/0! | AB22: =AC22-Z22 -> -1250 | AC22: =AD22/$O$4 -> 0 | AE22: =AD22/S22 -> #DIV/0! | AH22: =AR22*$AH$3 -> 0 | AI22: =AR22*$AI$3 -> 0 | AJ22: =AR22*$AJ$3 -> 0 | AK22: =AR22*$AK$3 -> 0 | AL22: 1250 | AM22: =AF22*$AM$3 -> 0 | AN22: =(R22*AG22)+AH22+AI22+AJ22+AK22+AL22+AM22 -> 1250 | AO22: =AP22/AQ22 -> #DIV/0! | AP22: =AQ22-AN22 -> -1250 | AQ22: =AR22/$O$4 -> 0 | AS22: =AR22/AG22 -> #DIV/0!
A23: C. BARA T. 5PCS + GAS B. 2PCS | B23: =B7*5+B13*2 -> 32300 | C23: =B23*$C$4 -> 26486 | D23: =C23/$D$4 -> 23861.261 | E23: 1 | F23: =P23*$F$3 -> 5192 | G23: =P23*$G$3 -> 3520 | H23: =P23*$H$3 -> 1980 | I23: =P23*$I$3 -> 792 | J23: 1250 | K23: =C23*$K$3*E23 -> 2118.88 | L23: =(D23*E23)+F23+G23+H23+I23+J23+K23 -> 38714.141 | M23: =N23/O23 -> 0.0233478 | N23: =O23-L23 -> 925.49838 | O23: =P23/$O$4 -> 39639.64 | P23: 44000 | Q23: =P23/E23 -> 44000 | T23: =AD23*$T$3 -> 0 | U23: =AD23*$U$3 -> 0 | V23: =AD23*$V$3 -> 0 | W23: =AD23*$W$3 -> 0 | X23: 1250 | Y23: =C23*$Y$3*S23 -> 0 | Z23: =(D23*S23)+T23+U23+V23+W23+X23+Y23 -> 1250 | AA23: =AB23/AC23 -> #DIV/0! | AB23: =AC23-Z23 -> -1250 | AC23: =AD23/$O$4 -> 0 | AE23: =AD23/S23 -> #DIV/0! | AH23: =AR23*$AH$3 -> 0 | AI23: =AR23*$AI$3 -> 0 | AJ23: =AR23*$AJ$3 -> 0 | AK23: =AR23*$AK$3 -> 0 | AL23: 1250 | AM23: =AF23*$AM$3 -> 0 | AN23: =(R23*AG23)+AH23+AI23+AJ23+AK23+AL23+AM23 -> 1250 | AO23: =AP23/AQ23 -> #DIV/0! | AP23: =AQ23-AN23 -> -1250 | AQ23: =AR23/$O$4 -> 0 | AS23: =AR23/AG23 -> #DIV/0!
A24: C. SUPERJET 1PCS + GAS B. 1PCS | B24: =B8+B13 -> 30900 | C24: =B24*$C$4 -> 25338 | D24: =C24/$D$4 -> 22827.027 | E24: 1 | F24: =P24*$F$3 -> 5015 | G24: =P24*$G$3 -> 3400 | H24: =P24*$H$3 -> 1912.5 | I24: =P24*$I$3 -> 765 | J24: 1250 | K24: =C24*$K$3*E24 -> 2027.04 | L24: =(D24*E24)+F24+G24+H24+I24+J24+K24 -> 37196.567 | M24: =N24/O24 -> 0.028513191 | N24: =O24-L24 -> 1091.7213 | O24: =P24/$O$4 -> 38288.288 | P24: 42500 | Q24: =P24/E24 -> 42500 | T24: =AD24*$T$3 -> 0 | U24: =AD24*$U$3 -> 0 | V24: =AD24*$V$3 -> 0 | W24: =AD24*$W$3 -> 0 | X24: 1250 | Y24: =C24*$Y$3*S24 -> 0 | Z24: =(D24*S24)+T24+U24+V24+W24+X24+Y24 -> 1250 | AA24: =AB24/AC24 -> #DIV/0! | AB24: =AC24-Z24 -> -1250 | AC24: =AD24/$O$4 -> 0 | AE24: =AD24/S24 -> #DIV/0! | AH24: =AR24*$AH$3 -> 0 | AI24: =AR24*$AI$3 -> 0 | AJ24: =AR24*$AJ$3 -> 0 | AK24: =AR24*$AK$3 -> 0 | AL24: 1250 | AM24: =AF24*$AM$3 -> 0 | AN24: =(R24*AG24)+AH24+AI24+AJ24+AK24+AL24+AM24 -> 1250 | AO24: =AP24/AQ24 -> #DIV/0! | AP24: =AQ24-AN24 -> -1250 | AQ24: =AR24/$O$4 -> 0 | AS24: =AR24/AG24 -> #DIV/0!
A25: C. SUPERJET 2PCS + GAS B. 2PCS | B25: =B8*2+B13*2 -> 61800 | C25: =B25*$C$4 -> 50676 | D25: =C25/$D$4 -> 45654.054 | E25: 1 | F25: =P25*$F$3 -> 9794 | G25: =P25*$G$3 -> 6640 | H25: =P25*$H$3 -> 3735 | I25: =P25*$I$3 -> 1494 | J25: 1250 | K25: =C25*$K$3*E25 -> 4054.08 | L25: =(D25*E25)+F25+G25+H25+I25+J25+K25 -> 72621.134 | M25: =N25/O25 -> 0.028801701 | N25: =O25-L25 -> 2153.6407 | O25: =P25/$O$4 -> 74774.775 | P25: 83000 | Q25: =P25/E25 -> 83000 | T25: =AD25*$T$3 -> 0 | U25: =AD25*$U$3 -> 0 | V25: =AD25*$V$3 -> 0 | W25: =AD25*$W$3 -> 0 | X25: 1250 | Y25: =C25*$Y$3*S25 -> 0 | Z25: =(D25*S25)+T25+U25+V25+W25+X25+Y25 -> 1250
A26: C. SUPERJET 4PCS + GAS B. 1PCS | B26: =B8*4+B13 -> 105900 | C26: =B26*$C$4 -> 86838 | D26: =C26/$D$4 -> 78232.432 | E26: 1 | F26: =P26*$F$3 -> 16520 | G26: =P26*$G$3 -> 11200 | H26: =P26*$H$3 -> 6300 | I26: =P26*$I$3 -> 2520 | J26: 1250 | K26: =C26*$K$3*E26 -> 6947.04 | L26: =(D26*E26)+F26+G26+H26+I26+J26+K26 -> 122969.47 | M26: =N26/O26 -> 0.025027754 | N26: =O26-L26 -> 3156.6537 | O26: =P26/$O$4 -> 126126.13 | P26: 140000 | Q26: =P26/E26 -> 140000 | T26: =AD26*$T$3 -> 0 | U26: =AD26*$U$3 -> 0 | V26: =AD26*$V$3 -> 0 | W26: =AD26*$W$3 -> 0 | X26: 1250 | Y26: =C26*$Y$3*S26 -> 0 | Z26: =(D26*S26)+T26+U26+V26+W26+X26+Y26 -> 1250
A27: C. SUPERJET 4PCS + GAS B. 2PCS | B27: =B8*4+B13*2 -> 111800 | C27: =B27*$C$4 -> 91676 | D27: =C27/$D$4 -> 82590.991 | E27: 1 | F27: =P27*$F$3 -> 17405 | G27: =P27*$G$3 -> 11800 | H27: =P27*$H$3 -> 6637.5 | I27: =P27*$I$3 -> 2655 | J27: 1250 | K27: =C27*$K$3*E27 -> 7334.08 | L27: =(D27*E27)+F27+G27+H27+I27+J27+K27 -> 129672.57 | M27: =N27/O27 -> 0.024158957 | N27: =O27-L27 -> 3210.3119 | O27: =P27/$O$4 -> 132882.88 | P27: 147500 | Q27: =P27/E27 -> 147500 | T27: =AD27*$T$3 -> 0 | U27: =AD27*$U$3 -> 0 | V27: =AD27*$V$3 -> 0 | W27: =AD27*$W$3 -> 0 | X27: 1250 | Y27: =C27*$Y$3*S27 -> 0 | Z27: =(D27*S27)+T27+U27+V27+W27+X27+Y27 -> 1250
F28: =P28*$F$3 -> 0 | G28: =P28*$G$3 -> 0 | H28: =P28*$H$3 -> 0 | I28: =P28*$I$3 -> 0 | J28: 1250 | K28: =C28*$K$3*E28 -> 0 | L28: =(D28*E28)+F28+G28+H28+I28+J28+K28 -> 1250 | T28: =AD28*$T$3 -> 0 | U28: =AD28*$U$3 -> 0 | V28: =AD28*$V$3 -> 0 | W28: =AD28*$W$3 -> 0 | X28: 1250 | Y28: =C28*$Y$3*S28 -> 0 | Z28: =(D28*S28)+T28+U28+V28+W28+X28+Y28 -> 1250
A29: POWERJET 1PCS + GAS B. 1PCS | B29: =B12+B13 -> 78900 | C29: =B29*$C$4 -> 64698 | D29: =C29/$D$4 -> 58286.486 | E29: 1 | F29: =P29*$F$3 -> 12390 | G29: =P29*$G$3 -> 8400 | H29: =P29*$H$3 -> 4725 | I29: =P29*$I$3 -> 1890 | J29: 1250 | K29: =C29*$K$3*E29 -> 5175.84 | L29: =(D29*E29)+F29+G29+H29+I29+J29+K29 -> 92117.326 | M29: =N29/O29 -> 0.026188263 | N29: =O29-L29 -> 2477.2681 | O29: =P29/$O$4 -> 94594.595 | P29: 105000 | Q29: =P29/E29 -> 105000 | T29: =AD29*$T$3 -> 0 | U29: =AD29*$U$3 -> 0 | V29: =AD29*$V$3 -> 0 | W29: =AD29*$W$3 -> 0 | X29: 1250 | Y29: =C29*$Y$3*S29 -> 0 | Z29: =(D29*S29)+T29+U29+V29+W29+X29+Y29 -> 1250 | AA29: =AB29/AC29 -> #DIV/0! | AB29: =AC29-Z29 -> -1250 | AC29: =AD29/$O$4 -> 0 | AE29: =AD29/S29 -> #DIV/0! | AH29: =AR29*$AH$3 -> 0 | AI29: =AR29*$AI$3 -> 0 | AJ29: =AR29*$AJ$3 -> 0 | AK29: =AR29*$AK$3 -> 0 | AL29: 1250 | AM29: =AF29*$AM$3 -> 0 | AN29: =(R29*AG29)+AH29+AI29+AJ29+AK29+AL29+AM29 -> 1250 | AO29: =AP29/AQ29 -> #DIV/0! | AP29: =AQ29-AN29 -> -1250 | AQ29: =AR29/$O$4 -> 0 | AS29: =AR29/AG29 -> #DIV/0!
A30: POWERJET 2PCS + GAS B. 2PCS | B30: =B12*2+B13*2 -> 157800 | C30: =B30*$C$4 -> 129396 | D30: =C30/$D$4 -> 116572.97 | E30: 1 | F30: =P30*$F$3 -> 24414.2 | G30: =P30*$G$3 -> 16552 | H30: =P30*$H$3 -> 9310.5 | I30: =P30*$I$3 -> 3724.2 | J30: 1250 | K30: =C30*$K$3*E30 -> 10351.68 | L30: =(D30*E30)+F30+G30+H30+I30+J30+K30 -> 182175.55 | M30: =N30/O30 -> 0.022644448 | N30: =O30-L30 -> 4220.8434 | O30: =P30/$O$4 -> 186396.4 | P30: 206900 | Q30: =P30/E30 -> 206900 | T30: =AD30*$T$3 -> 0 | U30: =AD30*$U$3 -> 0 | V30: =AD30*$V$3 -> 0 | W30: =AD30*$W$3 -> 0 | X30: 1250 | Y30: =C30*$Y$3*S30 -> 0 | Z30: =(D30*S30)+T30+U30+V30+W30+X30+Y30 -> 1250 | AA30: =AB30/AC30 -> #DIV/0! | AB30: =AC30-Z30 -> -1250 | AC30: =AD30/$O$4 -> 0 | AE30: =AD30/S30 -> #DIV/0! | AH30: =AR30*$AH$3 -> 0 | AI30: =AR30*$AI$3 -> 0 | AJ30: =AR30*$AJ$3 -> 0 | AK30: =AR30*$AK$3 -> 0 | AL30: 1250 | AM30: =AF30*$AM$3 -> 0 | AN30: =(R30*AG30)+AH30+AI30+AJ30+AK30+AL30+AM30 -> 1250 | AO30: =AP30/AQ30 -> #DIV/0! | AP30: =AQ30-AN30 -> -1250 | AQ30: =AR30/$O$4 -> 0 | AS30: =AR30/AG30 -> #DIV/0!
A31: IDEA 1PCS + GAS B 1PCS | B31: =B9+B13 -> 15900 | C31: =B31*$C$4 -> 13038 | D31: =C31/$D$4 -> 11745.946 | E31: 1 | F31: =P31*$F$3 -> 2773 | G31: =P31*$G$3 -> 1880 | H31: =P31*$H$3 -> 1057.5 | I31: =P31*$I$3 -> 423 | J31: 1250 | K31: =C31*$K$3*E31 -> 1043.04 | L31: =(D31*E31)+F31+G31+H31+I31+J31+K31 -> 20172.486 | M31: =N31/O31 -> 0.04717194 | N31: =O31-L31 -> 998.68523 | O31: =P31/$O$4 -> 21171.171 | P31: 23500 | Q31: =P31/E31 -> 23500 | T31: =AD31*$T$3 -> 0 | U31: =AD31*$U$3 -> 0 | V31: =AD31*$V$3 -> 0 | W31: =AD31*$W$3 -> 0 | X31: 1250 | Y31: =C31*$Y$3*S31 -> 0 | Z31: =(D31*S31)+T31+U31+V31+W31+X31+Y31 -> 1250 | AA31: =AB31/AC31 -> #DIV/0! | AB31: =AC31-Z31 -> -1250 | AC31: =AD31/$O$4 -> 0 | AE31: =AD31/S31 -> #DIV/0! | AH31: =AR31*$AH$3 -> 0 | AI31: =AR31*$AI$3 -> 0 | AJ31: =AR31*$AJ$3 -> 0 | AK31: =AR31*$AK$3 -> 0 | AL31: 1250 | AM31: =AF31*$AM$3 -> 0 | AN31: =(R31*AG31)+AH31+AI31+AJ31+AK31+AL31+AM31 -> 1250 | AO31: =AP31/AQ31 -> #DIV/0! | AP31: =AQ31-AN31 -> -1250 | AQ31: =AR31/$O$4 -> 0 | AS31: =AR31/AG31 -> #DIV/0!
A32: IDEA 2PCS + GAS 2PCS | B32: =B9*2+B13*2 -> 31800 | C32: =B32*$C$4 -> 26076 | D32: =C32/$D$4 -> 23491.892 | E32: 1 | F32: =P32*$F$3 -> 5256.9 | G32: =P32*$G$3 -> 3564 | H32: =P32*$H$3 -> 2004.75 | I32: =P32*$I$3 -> 801.9 | J32: 1250 | K32: =C32*$K$3*E32 -> 2086.08 | L32: =(D32*E32)+F32+G32+H32+I32+J32+K32 -> 38455.522 | M32: =N32/O32 -> 0.041848949 | N32: =O32-L32 -> 1679.6132 | O32: =P32/$O$4 -> 40135.135 | P32: 44550 | Q32: =P32/E32 -> 44550 | T32: =AD32*$T$3 -> 0 | U32: =AD32*$U$3 -> 0 | V32: =AD32*$V$3 -> 0 | W32: =AD32*$W$3 -> 0 | X32: 1250 | Y32: =C32*$Y$3*S32 -> 0 | Z32: =(D32*S32)+T32+U32+V32+W32+X32+Y32 -> 1250 | AA32: =AB32/AC32 -> #DIV/0! | AB32: =AC32-Z32 -> -1250 | AC32: =AD32/$O$4 -> 0 | AE32: =AD32/S32 -> #DIV/0! | AH32: =AR32*$AH$3 -> 0 | AI32: =AR32*$AI$3 -> 0 | AJ32: =AR32*$AJ$3 -> 0 | AK32: =AR32*$AK$3 -> 0 | AL32: 1250 | AM32: =AF32*$AM$3 -> 0 | AN32: =(R32*AG32)+AH32+AI32+AJ32+AK32+AL32+AM32 -> 1250 | AO32: =AP32/AQ32 -> #DIV/0! | AP32: =AQ32-AN32 -> -1250 | AQ32: =AR32/$O$4 -> 0 | AS32: =AR32/AG32 -> #DIV/0!
A33: C. FLEXIE 1PCS + GAS B. 1PCS | C33: =B33*$C$4 -> 0 | D33: =C33/$D$4 -> 0 | F33: =P33*$F$3 -> 0 | G33: =P33*$G$3 -> 0 | H33: =P33*$H$3 -> 0 | I33: =P33*$I$3 -> 0 | J33: 1250 | K33: =C33*$K$3*E33 -> 0 | L33: =(D33*E33)+F33+G33+H33+I33+J33+K33 -> 1250 | T33: =AD33*$T$3 -> 0 | U33: =AD33*$U$3 -> 0 | V33: =AD33*$V$3 -> 0 | W33: =AD33*$W$3 -> 0 | X33: 1250 | Y33: =C33*$Y$3*S33 -> 0 | Z33: =(D33*S33)+T33+U33+V33+W33+X33+Y33 -> 1250
A34: C. FLEXIE W. 1PCS + GAS B. 1PCS | B34: =B11+B13 -> 23900 | C34: =B34*$C$4 -> 19598 | D34: =C34/$D$4 -> 17655.856 | E34: 1 | F34: =P34*$F$3 -> 3953 | G34: =P34*$G$3 -> 2680 | H34: =P34*$H$3 -> 1507.5 | I34: =P34*$I$3 -> 603 | J34: 1250 | K34: =C34*$K$3*E34 -> 1567.84 | L34: =(D34*E34)+F34+G34+H34+I34+J34+K34 -> 29217.196 | M34: =N34/O34 -> 0.031907839 | N34: =O34-L34 -> 962.98432 | O34: =P34/$O$4 -> 30180.18 | P34: 33500 | Q34: =P34/E34 -> 33500 | T34: =AD34*$T$3 -> 0 | U34: =AD34*$U$3 -> 0 | V34: =AD34*$V$3 -> 0 | W34: =AD34*$W$3 -> 0 | X34: 1250 | Y34: =C34*$Y$3*S34 -> 0 | Z34: =(D34*S34)+T34+U34+V34+W34+X34+Y34 -> 1250 | AA34: =AB34/AC34 -> #DIV/0! | AB34: =AC34-Z34 -> -1250 | AC34: =AD34/$O$4 -> 0 | AE34: =AD34/S34 -> #DIV/0! | AH34: =AR34*$AH$3 -> 0 | AI34: =AR34*$AI$3 -> 0 | AJ34: =AR34*$AJ$3 -> 0 | AK34: =AR34*$AK$3 -> 0 | AL34: 1250 | AM34: =AF34*$AM$3 -> 0 | AN34: =(R34*AG34)+AH34+AI34+AJ34+AK34+AL34+AM34 -> 1250 | AO34: =AP34/AQ34 -> #DIV/0! | AP34: =AQ34-AN34 -> -1250 | AQ34: =AR34/$O$4 -> 0 | AS34: =AR34/AG34 -> #DIV/0!
A35: C. FLEXIE W. 2PCS + GAS B. 2PCS | B35: =B11*2+B13*2 -> 47800 | C35: =B35*$C$4 -> 39196 | D35: =C35/$D$4 -> 35311.712 | E35: 1 | F35: =P35*$F$3 -> 7534.89 | G35: =P35*$G$3 -> 5108.4 | H35: =P35*$H$3 -> 2873.475 | I35: =P35*$I$3 -> 1149.39 | J35: 1250 | K35: =C35*$K$3*E35 -> 3135.68 | L35: =(D35*E35)+F35+G35+H35+I35+J35+K35 -> 56363.547 | M35: =N35/O35 -> 0.020224934 | N35: =O35-L35 -> 1163.4803 | O35: =P35/$O$4 -> 57527.027 | P35: 63855 | Q35: =P35/E35 -> 63855 | T35: =AD35*$T$3 -> 0 | U35: =AD35*$U$3 -> 0 | V35: =AD35*$V$3 -> 0 | W35: =AD35*$W$3 -> 0 | X35: 1250 | Y35: =C35*$Y$3*S35 -> 0 | Z35: =(D35*S35)+T35+U35+V35+W35+X35+Y35 -> 1250 | AA35: =AB35/AC35 -> #DIV/0! | AB35: =AC35-Z35 -> -1250 | AC35: =AD35/$O$4 -> 0 | AE35: =AD35/S35 -> #DIV/0! | AH35: =AR35*$AH$3 -> 0 | AI35: =AR35*$AI$3 -> 0 | AJ35: =AR35*$AJ$3 -> 0 | AK35: =AR35*$AK$3 -> 0 | AL35: 1250 | AM35: =AF35*$AM$3 -> 0 | AN35: =(R35*AG35)+AH35+AI35+AJ35+AK35+AL35+AM35 -> 1250 | AO35: =AP35/AQ35 -> #DIV/0! | AP35: =AQ35-AN35 -> -1250 | AQ35: =AR35/$O$4 -> 0 | AS35: =AR35/AG35 -> #DIV/0!
A36: JETFLIP 1PCS + GAS B. 1PCS | B36: =B19+B13 -> 54900 | C36: =B36*$C$4 -> 45018 | D36: =C36/$D$4 -> 40556.757 | E36: 1 | F36: =P36*$F$3 -> 8673 | G36: =P36*$G$3 -> 5880 | H36: =P36*$H$3 -> 3307.5 | I36: =P36*$I$3 -> 1323 | J36: 1250 | K36: =C36*$K$3*E36 -> 3601.44 | L36: =(D36*E36)+F36+G36+H36+I36+J36+K36 -> 64591.697 | M36: =N36/O36 -> 0.024533559 | N36: =O36-L36 -> 1624.5195 | O36: =P36/$O$4 -> 66216.216 | P36: 73500 | Q36: =P36/E36 -> 73500 | T36: =AD36*$T$3 -> 0 | U36: =AD36*$U$3 -> 0 | V36: =AD36*$V$3 -> 0 | W36: =AD36*$W$3 -> 0 | X36: 1250 | Y36: =C36*$Y$3*S36 -> 0 | Z36: =(D36*S36)+T36+U36+V36+W36+X36+Y36 -> 1250 | AA36: =AB36/AC36 -> #DIV/0! | AB36: =AC36-Z36 -> -1250 | AC36: =AD36/$O$4 -> 0 | AE36: =AD36/S36 -> #DIV/0! | AH36: =AR36*$AH$3 -> 0 | AI36: =AR36*$AI$3 -> 0 | AJ36: =AR36*$AJ$3 -> 0 | AK36: =AR36*$AK$3 -> 0 | AL36: 1250 | AM36: =AF36*$AM$3 -> 0 | AN36: =(R36*AG36)+AH36+AI36+AJ36+AK36+AL36+AM36 -> 1250 | AO36: =AP36/AQ36 -> #DIV/0! | AP36: =AQ36-AN36 -> -1250 | AQ36: =AR36/$O$4 -> 0 | AS36: =AR36/AG36 -> #DIV/0!
A37: CASE ORIGINAL | B37: 2500 | C37: =B37 -> 2500 | D37: =C37/$D$4 -> 2252.2523 | E37: 1 | F37: =P37*$F$3 -> 755.2 | G37: =P37*$G$3 -> 512 | H37: =P37*$H$3 -> 288 | I37: =P37*$I$3 -> 115.2 | J37: 1250 | K37: =C37*$K$3*E37 -> 200 | L37: =(D37*E37)+F37+G37+H37+I37+J37+K37 -> 5372.6523 | M37: =N37/O37 -> 0.068180625 | N37: =O37-L37 -> 393.11351 | O37: =P37/$O$4 -> 5765.7658 | P37: 6400 | Q37: =P37/E37 -> 6400 | T37: =AD37*$T$3 -> 0 | U37: =AD37*$U$3 -> 0 | V37: =AD37*$V$3 -> 0 | W37: =AD37*$W$3 -> 0 | X37: 1250 | Y37: =C37*$Y$3*S37 -> 0 | Z37: =(D37*S37)+T37+U37+V37+W37+X37+Y37 -> 1250 | AA37: =AB37/AC37 -> #DIV/0! | AB37: =AC37-Z37 -> -1250 | AC37: =AD37/$O$4 -> 0 | AE37: =AD37/S37 -> #DIV/0! | AH37: =AR37*$AH$3 -> 0 | AI37: =AR37*$AI$3 -> 0 | AJ37: =AR37*$AJ$3 -> 0 | AK37: =AR37*$AK$3 -> 0 | AL37: 1250 | AM37: =AF37*$AM$3 -> 0 | AN37: =(R37*AG37)+AH37+AI37+AJ37+AK37+AL37+AM37 -> 1250 | AO37: =AP37/AQ37 -> #DIV/0! | AP37: =AQ37-AN37 -> -1250 | AQ37: =AR37/$O$4 -> 0 | AS37: =AR37/AG37 -> #DIV/0!
A38: CROCKIE ORIGINAL + CASE | B38: =B5+B37 -> 5850 | C38: =B38*$C$4 -> 4797 | D38: =C38/$D$4 -> 4321.6216 | E38: 1 | F38: =P38*$F$3 -> 1168.2 | G38: =P38*$G$3 -> 792 | H38: =P38*$H$3 -> 445.5 | I38: =P38*$I$3 -> 178.2 | J38: 1250 | K38: =C38*$K$3*E38 -> 383.76 | L38: =(D38*E38)+F38+G38+H38+I38+J38+K38 -> 8539.2816 | M38: =N38/O38 -> 0.042565394 | N38: =O38-L38 -> 379.6373 | O38: =P38/$O$4 -> 8918.9189 | P38: 9900 | Q38: =P38/E38 -> 9900 | T38: =AD38*$T$3 -> 0 | U38: =AD38*$U$3 -> 0 | V38: =AD38*$V$3 -> 0 | W38: =AD38*$W$3 -> 0 | X38: 1250 | Y38: =C38*$Y$3*S38 -> 0 | Z38: =(D38*S38)+T38+U38+V38+W38+X38+Y38 -> 1250 | AA38: =AB38/AC38 -> #DIV/0! | AB38: =AC38-Z38 -> -1250 | AC38: =AD38/$O$4 -> 0 | AE38: =AD38/S38 -> #DIV/0! | AH38: =AR38*$AH$3 -> 0 | AI38: =AR38*$AI$3 -> 0 | AJ38: =AR38*$AJ$3 -> 0 | AK38: =AR38*$AK$3 -> 0 | AL38: 1250 | AM38: =AF38*$AM$3 -> 0 | AN38: =(R38*AG38)+AH38+AI38+AJ38+AK38+AL38+AM38 -> 1250 | AO38: =AP38/AQ38 -> #DIV/0! | AP38: =AQ38-AN38 -> -1250 | AQ38: =AR38/$O$4 -> 0 | AS38: =AR38/AG38 -> #DIV/0!
A39: CROCKIE ORIGINAL 5 + CASE | B39: =B5*5+B37 -> 19250 | C39: =B39*$C$4 -> 15785 | D39: =C39/$D$4 -> 14220.721 | E39: 1 | F39: =P39*$F$3 -> 3658 | G39: =P39*$G$3 -> 2480 | H39: =P39*$H$3 -> 1395 | I39: =P39*$I$3 -> 558 | J39: 1250 | K39: =C39*$K$3*E39 -> 1262.8 | L39: =(D39*E39)+F39+G39+H39+I39+J39+K39 -> 24824.521 | M39: =N39/O39 -> 0.111122 | N39: =O39-L39 -> 3103.4072 | O39: =P39/$O$4 -> 27927.928 | P39: 31000 | Q39: =P39/E39 -> 31000 | T39: =AD39*$T$3 -> 0 | U39: =AD39*$U$3 -> 0 | V39: =AD39*$V$3 -> 0 | W39: =AD39*$W$3 -> 0 | X39: 1250 | Y39: =C39*$Y$3*S39 -> 0 | Z39: =(D39*S39)+T39+U39+V39+W39+X39+Y39 -> 1250 | AA39: =AB39/AC39 -> #DIV/0! | AB39: =AC39-Z39 -> -1250 | AC39: =AD39/$O$4 -> 0 | AE39: =AD39/S39 -> #DIV/0! | AH39: =AR39*$AH$3 -> 0 | AI39: =AR39*$AI$3 -> 0 | AJ39: =AR39*$AJ$3 -> 0 | AK39: =AR39*$AK$3 -> 0 | AL39: 1250 | AM39: =AF39*$AM$3 -> 0 | AN39: =(R39*AG39)+AH39+AI39+AJ39+AK39+AL39+AM39 -> 1250 | AO39: =AP39/AQ39 -> #DIV/0! | AP39: =AQ39-AN39 -> -1250 | AQ39: =AR39/$O$4 -> 0 | AS39: =AR39/AG39 -> #DIV/0!
A40: CASE BARA | B40: 3000 | C40: =B40 -> 3000 | D40: =C40/$D$4 -> 2702.7027 | E40: 1 | F40: =P40*$F$3 -> 873.2 | G40: =P40*$G$3 -> 592 | H40: =P40*$H$3 -> 333 | I40: =P40*$I$3 -> 133.2 | J40: 1250 | K40: =C40*$K$3*E40 -> 240 | L40: =(D40*E40)+F40+G40+H40+I40+J40+K40 -> 6124.1027 | M40: =N40/O40 -> 0.081384595 | N40: =O40-L40 -> 542.56396 | O40: =P40/$O$4 -> 6666.6667 | P40: 7400 | Q40: =P40/E40 -> 7400 | T40: =AD40*$T$3 -> 0 | U40: =AD40*$U$3 -> 0 | V40: =AD40*$V$3 -> 0 | W40: =AD40*$W$3 -> 0 | X40: 1250 | Y40: =C40*$Y$3*S40 -> 0 | Z40: =(D40*S40)+T40+U40+V40+W40+X40+Y40 -> 1250 | AA40: =AB40/AC40 -> #DIV/0! | AB40: =AC40-Z40 -> -1250 | AC40: =AD40/$O$4 -> 0 | AE40: =AD40/S40 -> #DIV/0! | AH40: =AR40*$AH$3 -> 0 | AI40: =AR40*$AI$3 -> 0 | AJ40: =AR40*$AJ$3 -> 0 | AK40: =AR40*$AK$3 -> 0 | AL40: 1250 | AM40: =AF40*$AM$3 -> 0 | AN40: =(R40*AG40)+AH40+AI40+AJ40+AK40+AL40+AM40 -> 1250 | AO40: =AP40/AQ40 -> #DIV/0! | AP40: =AQ40-AN40 -> -1250 | AQ40: =AR40/$O$4 -> 0 | AS40: =AR40/AG40 -> #DIV/0!
...

Sheet HPP STAR
A1: Nama Produk STAR | B1: HARGA NASIONAL | C1: HARGA NASIONAL (PCS) | D1: HARGA NASIONAL (PCS) | E1: ECOM (PCS) | S1: ECOM (PCS/PACK) / BOX | AG1: ECOM CTN
E2: min (PCS) | F2: ADM MARKETPLACE (INC. PPN) | J2: Biaya | K2: BIAYA OPS | L2: HPP | M2: MARGIN ECOM | N2: PROFIT | O2: HARGA JUAL (PCS) | Q2: Harga Jual /pcs | S2: PACK (PCS) | T2: ADM MARKETPLACE (INC. PPN) | X2: Biaya | Y2: BIAYA OPS | Z2: HPP | AA2: MARGIN ECOM | AB2: PROFIT | AC2: HARGA JUAL (PACK) | AE2: HARGA JUAL SATUAN | AG2: (PCS) | AH2: ADM MARKETPLACE (INC. PPN) | AL2: Biaya | AM2: BIAYA OPS | AN2: HPP | AO2: MARGIN ECOM | AP2: PROFIT | AQ2: HARGA JUAL (PCS) | AS2: HARGA JUAL SATUAN) | AT2: CTN (PCS) | AU2: ADM MARKETPLACE (INC. PPN) | AV2: Biaya | AW2: BIAYA OPS | AX2: HPP | AY2: MARGIN CMS | AZ2: PROFIT | BA2: HARGA JUAL (PCS) | BC2: HARGA JUAL (BOX)
C3: (INC PPN) | D3: (EXC PPN) | F3: 0.1 | G3: 0.045 | H3: 0.08 | I3: 0 | J3: 1250 | K3: 0.07 | L3: (EXC PPN) | M3: 0.025 | O3: (EXC PPN) | P3: (INCL PPN) | T3: 0.1 | U3: 0.05 | V3: 0.08 | W3: 0 | X3: 1250 | Y3: 0.07 | Z3: (EXC PPN) | AA3: 0.025 | AC3: (EXC PPN) | AD3: (INC PPN) | AH3: 0.117 | AI3: 0.06 | AJ3: 0.045 | AK3: 0 | AM3: 0.05 | AN3: (EXC PPN) | AO3: 0.02 | AQ3: (EXC PPN) | AR3: (INC PPN) | AU3: 0.17 | AW3: 0.04 | AX3: (EXC PPN) | BA3: (EXC PPN) | BB3: (INC PPN)
A4: Per Pcs | C4: 0.82 | D4: 1.11 | O4: 1.11
A5: CROCKIE ORIGINAL | B5: ='HPP MALL'!B5 -> 3350 | C5: =B5*$C$4 -> 2747 | D5: =C5/$D$4 -> 2474.7748 | E5: 3 | F5: =P5*$F$3 -> 1500 | G5: =P5*$G$3 -> 675 | H5: =P5*$H$3 -> 1200 | I5: =P5*$I$3 -> 0 | J5: 1250 | K5: =D5*$K$3*E5 -> 519.7027 | L5: =(D5*E5)+F5+G5+H5+I5+J5+K5 -> 12569.027 | M5: =N5/O5 -> 0.069892 | N5: =O5-L5 -> 944.48649 | O5: =P5/$O$4 -> 13513.514 | P5: 15000 | Q5: =P5/E5 -> 5000 | S5: 50 | T5: =AD5*$T$3 -> 20500 | U5: =AD5*$U$3 -> 10250 | V5: =AD5*$V$3 -> 16400 | W5: =AD5*$W$3 -> 0 | X5: 1250 | Y5: =D5*$Y$3*S5 -> 8661.7117 | Z5: =(D5*S5)+T5+U5+V5+W5+X5+Y5 -> 180800.45 | AA5: =AB5/AC5 -> 0.021031707 | AB5: =AC5-Z5 -> 3884.2342 | AC5: =AD5/$O$4 -> 184684.68 | AD5: 205000 | AE5: =AD5/S5 -> 4100 | AG5: 500 | AH5: =AR5*$T$3 -> 196800 | AI5: =AR5*$U$3 -> 98400 | AJ5: =AR5*$V$3 -> 157440 | AK5: =AR5*$W$3 -> 0 | AL5: 1250 | AM5: =D5*$AM$3*AG5 -> 61869.369 | AN5: =(D5*AG5)+AH5+AI5+AJ5+AK5+AL5+AM5 -> 1753146.8 | AO5: =AP5/AQ5 -> 0.01118247 | AP5: =AQ5-AN5 -> 19826.216 | AQ5: =AR5/$O$4 -> 1772973 | AR5: 1968000 | AS5: =AR5/AG5 -> 3936
A6: CROCKIE MAGNET SUPER | B6: ='HPP MALL'!B6 -> 3500 | C6: =B6*$C$4 -> 2870 | D6: =C6/$D$4 -> 2585.5856 | E6: 3 | F6: =P6*$F$3 -> 1580 | G6: =P6*$G$3 -> 711 | H6: =P6*$H$3 -> 1264 | I6: =P6*$I$3 -> 0 | J6: 1250 | K6: =D6*$K$3*E6 -> 542.97297 | L6: =(D6*E6)+F6+G6+H6+I6+J6+K6 -> 13104.73 | M6: =N6/O6 -> 0.079351266 | N6: =O6-L6 -> 1129.5045 | O6: =P6/$O$4 -> 14234.234 | P6: 15800 | Q6: =P6/E6 -> 5266.6667 | S6: 50 | T6: =AD6*$T$3 -> 21400 | U6: =AD6*$U$3 -> 10700 | V6: =AD6*$V$3 -> 17120 | W6: =AD6*$W$3 -> 0 | X6: 1250 | Y6: =D6*$K$3*S6 -> 9049.5495 | Z6: =(D6*S6)+T6+U6+V6+W6+X6+Y6 -> 188798.83 | AA6: =AB6/AC6 -> 0.020716355 | AB6: =AC6-Z6 -> 3993.964 | AC6: =AD6/$O$4 -> 192792.79 | AD6: 214000 | AE6: =AD6/S6 -> 4280 | AG6: 500 | AH6: =AR6*$AH$3 -> 240669 | AI6: =AR6*$AI$3 -> 123420 | AJ6: =AR6*$AJ$3 -> 92565 | AK6: =AR6*$AK$3 -> 0 | AL6: 1250 | AM6: =D6*$AM$3*AG6 -> 64639.64 | AN6: =(D6*AG6)+AH6+AI6+AJ6+AK6+AL6+AM6 -> 1815336.4 | AO6: =AP6/AQ6 -> 0.020406689 | AP6: =AQ6-AN6 -> 37816.721 | AQ6: =AR6/$O$4 -> 1853153.2 | AR6: 2057000 | AS6: =AR6/AG6 -> 4114
A7: CROCKIE BARA TURBO | B7: ='HPP MALL'!B7 -> 4100 | C7: =B7*$C$4 -> 3362 | D7: =C7/$D$4 -> 3028.8288 | E7: 3 | F7: =P7*$F$3 -> 1700 | G7: =P7*$G$3 -> 765 | H7: =P7*$H$3 -> 1360 | I7: =P7*$I$3 -> 0 | J7: 1250 | K7: =D7*$K$3*E7 -> 636.05405 | L7: =(D7*E7)+F7+G7+H7+I7+J7+K7 -> 14797.541 | M7: =N7/O7 -> 0.033807647 | N7: =O7-L7 -> 517.77477 | O7: =P7/$O$4 -> 15315.315 | P7: 17000 | Q7: =P7/E7 -> 5666.6667 | S7: 25 | T7: =AD7*$T$3 -> 12600 | U7: =AD7*$U$3 -> 6300 | V7: =AD7*$V$3 -> 10080 | W7: =AD7*$W$3 -> 0 | X7: 1250 | Y7: =D7*$K$3*S7 -> 5300.4505 | Z7: =(D7*S7)+T7+U7+V7+W7+X7+Y7 -> 111251.17 | AA7: =AB7/AC7 -> 0.019930159 | AB7: =AC7-Z7 -> 2262.3423 | AC7: =AD7/$O$4 -> 113513.51 | AD7: 126000 | AE7: =AD7/S7 -> 5040 | AG7: 500 | AH7: =AR7*$AH$3 -> 279630 | AI7: =AR7*$AI$3 -> 143400 | AJ7: =AR7*$AJ$3 -> 107550 | AK7: =AR7*$AK$3 -> 0 | AL7: 1250 | AM7: =D7*$AM$3*AG7 -> 75720.721 | AN7: =(D7*AG7)+AH7+AI7+AJ7+AK7+AL7+AM7 -> 2121965.1 | AO7: =AP7/AQ7 -> 0.014484812 | AP7: =AQ7-AN7 -> 31188.018 | AQ7: =AR7/$O$4 -> 2153153.2 | AR7: 2390000 | AS7: =AR7/AG7 -> 4780
A8: CROCKIE SUPER JET | B8: ='HPP MALL'!B8 -> 25000 | C8: =B8*$C$4 -> 20500 | D8: =C8/$D$4 -> 18468.468 | E8: 1 | F8: =P8*$F$3 -> 3260 | G8: =P8*$G$3 -> 1467 | H8: =P8*$H$3 -> 2608 | I8: =P8*$I$3 -> 0 | J8: 1250 | K8: =D8*$K$3*E8 -> 1292.7928 | L8: =(D8*E8)+F8+G8+H8+I8+J8+K8 -> 28346.261 | M8: =N8/O8 -> 0.03483589 | N8: =O8-L8 -> 1023.1081 | O8: =P8/$O$4 -> 29369.369 | P8: 32600 | Q8: =P8/E8 -> 32600 | S8: 4 | T8: =AD8*$T$3 -> 12450 | U8: =AD8*$U$3 -> 6225 | V8: =AD8*$V$3 -> 9960 | W8: =AD8*$W$3 -> 0 | X8: 1250 | Y8: =D8*$K$3*S8 -> 5171.1712 | Z8: =(D8*S8)+T8+U8+V8+W8+X8+Y8 -> 108930.04 | AA8: =AB8/AC8 -> 0.028816466 | AB8: =AC8-Z8 -> 3232.1171 | AC8: =AD8/$O$4 -> 112162.16 | AD8: 124500 | AE8: =AD8/S8 -> 31125 | AG8: 100 | AH8: =AR8*$AH$3 -> 0 | AI8: =AR8*$AI$3 -> 0 | AJ8: =AR8*$AJ$3 -> 0 | AK8: =AR8*$AK$3 -> 0 | AL8: 1250 | AM8: =D8*$AM$3*AG8 -> 92342.342 | AN8: =(D8*AG8)+AH8+AI8+AJ8+AK8+AL8+AM8 -> 1940439.2 | AO8: =AP8/AQ8 -> #DIV/0! | AP8: =AQ8-AN8 -> -1940439.2 | AQ8: =AR8/$O$4 -> 0 | AS8: =AR8/AG8 -> 0
A9: CROCKIE IDEA | B9: ='HPP MALL'!B9 -> 10000 | C9: =B9*$C$4 -> 8200 | D9: =C9/$D$4 -> 7387.3874 | E9: 1 | F9: =P9*$F$3 -> 1450 | G9: =P9*$G$3 -> 652.5 | H9: =P9*$H$3 -> 1160 | I9: =P9*$I$3 -> 0 | J9: 1250 | K9: =D9*$K$3*E9 -> 517.11712 | L9: =(D9*E9)+F9+G9+H9+I9+J9+K9 -> 12417.004 | M9: =N9/O9 -> 0.049456897 | N9: =O9-L9 -> 646.05856 | O9: =P9/$O$4 -> 13063.063 | P9: 14500 | Q9: =P9/E9 -> 14500 | S9: 16 | T9: =AD9*$T$3 -> 19500 | U9: =AD9*$U$3 -> 9750 | V9: =AD9*$V$3 -> 15600 | W9: =AD9*$W$3 -> 0 | X9: 1250 | Y9: =D9*$K$3*S9 -> 8273.8739 | Z9: =(D9*S9)+T9+U9+V9+W9+X9+Y9 -> 172572.07 | AA9: =AB9/AC9 -> 0.017666667 | AB9: =AC9-Z9 -> 3103.6036 | AC9: =AD9/$O$4 -> 175675.68 | AD9: 195000 | AE9: =AD9/S9 -> 12187.5 | AH9: =AR9*$AH$3 -> 0 | AI9: =AR9*$AI$3 -> 0 | AJ9: =AR9*$AJ$3 -> 0 | AK9: =AR9*$AK$3 -> 0 | AL9: 1250 | AM9: =D9*$AM$3*AG9 -> 0 | AN9: =(D9*AG9)+AH9+AI9+AJ9+AK9+AL9+AM9 -> 1250 | AO9: =AP9/AQ9 -> #DIV/0! | AP9: =AQ9-AN9 -> -1250 | AQ9: =AR9/$O$4 -> 0 | AS9: =AR9/AG9 -> #DIV/0!
A10: CROCKIE FLEXIE | B10: ='HPP MALL'!B10 -> 15000 | C10: =B10*$C$4 -> 12300 | D10: =C10/$D$4 -> 11081.081 | E10: 1 | F10: =P10*$F$3 -> 2050 | G10: =P10*$G$3 -> 922.5 | H10: =P10*$H$3 -> 1640 | I10: =P10*$I$3 -> 0 | J10: 1250 | K10: =D10*$K$3*E10 -> 775.67568 | L10: =(D10*E10)+F10+G10+H10+I10+J10+K10 -> 17719.257 | M10: =N10/O10 -> 0.040567073 | N10: =O10-L10 -> 749.21171 | O10: =P10/$O$4 -> 18468.468 | P10: 20500 | Q10: =P10/E10 -> 20500 | S10: 4 | T10: =AD10*$T$3 -> 7450 | U10: =AD10*$U$3 -> 3725 | V10: =AD10*$V$3 -> 5960 | W10: =AD10*$W$3 -> 0 | X10: 1250 | Y10: =D10*$K$3*S10 -> 3102.7027 | Z10: =(D10*S10)+T10+U10+V10+W10+X10+Y10 -> 65812.027 | AA10: =AB10/AC10 -> 0.019444966 | AB10: =AC10-Z10 -> 1305.0901 | AC10: =AD10/$O$4 -> 67117.117 | AD10: 74500 | AE10: =AD10/S10 -> 18625 | AH10: =AR10*$AH$3 -> 0 | AI10: =AR10*$AI$3 -> 0 | AJ10: =AR10*$AJ$3 -> 0 | AK10: =AR10*$AK$3 -> 0 | AL10: 1250 | AM10: =D10*$AM$3*AG10 -> 0 | AN10: =(D10*AG10)+AH10+AI10+AJ10+AK10+AL10+AM10 -> 1250 | AO10: =AP10/AQ10 -> #DIV/0! | AP10: =AQ10-AN10 -> -1250 | AQ10: =AR10/$O$4 -> 0 | AS10: =AR10/AG10 -> #DIV/0!
A11: CROCKIE FLEXIE WINDPROOF | B11: ='HPP MALL'!B11 -> 18000 | C11: =B11*$C$4 -> 14760 | D11: =C11/$D$4 -> 13297.297 | E11: 1 | F11: =P11*$F$3 -> 2400 | G11: =P11*$G$3 -> 1080 | H11: =P11*$H$3 -> 1920 | I11: =P11*$I$3 -> 0 | J11: 1250 | K11: =D11*$K$3*E11 -> 930.81081 | L11: =(D11*E11)+F11+G11+H11+I11+J11+K11 -> 20878.108 | M11: =N11/O11 -> 0.0343875 | N11: =O11-L11 -> 743.51351 | O11: =P11/$O$4 -> 21621.622 | P11: 24000 | Q11: =P11/E11 -> 24000 | T11: =AD11*$T$3 -> 0 | U11: =AD11*$U$3 -> 0 | V11: =AD11*$V$3 -> 0 | W11: =AD11*$W$3 -> 0 | X11: 1250 | Y11: =D11*$K$3*S11 -> 0 | Z11: =(D11*S11)+T11+U11+V11+W11+X11+Y11 -> 1250 | AA11: =AB11/AC11 -> #DIV/0! | AB11: =AC11-Z11 -> -1250 | AC11: =AD11/$O$4 -> 0 | AE11: =AD11/S11 -> #DIV/0! | AH11: =AR11*$AH$3 -> 0 | AI11: =AR11*$AI$3 -> 0 | AJ11: =AR11*$AJ$3 -> 0 | AK11: =AR11*$AK$3 -> 0 | AL11: 1250 | AM11: =D11*$AM$3*AG11 -> 0 | AN11: =(D11*AG11)+AH11+AI11+AJ11+AK11+AL11+AM11 -> 1250 | AO11: =AP11/AQ11 -> #DIV/0! | AP11: =AQ11-AN11 -> -1250 | AQ11: =AR11/$O$4 -> 0 | AS11: =AR11/AG11 -> #DIV/0!
A12: CROCKIE POWER JET | B12: ='HPP MALL'!B12 -> 73000 | C12: =B12*$C$4 -> 59860 | D12: =C12/$D$4 -> 53927.928 | E12: 1 | F12: =P12*$F$3 -> 9050 | G12: =P12*$G$3 -> 4072.5 | H12: =P12*$H$3 -> 7240 | I12: =P12*$I$3 -> 0 | J12: 1250 | K12: =D12*$K$3*E12 -> 3774.955 | L12: =(D12*E12)+F12+G12+H12+I12+J12+K12 -> 79315.383 | M12: =N12/O12 -> 0.027181492 | N12: =O12-L12 -> 2216.1486 | O12: =P12/$O$4 -> 81531.532 | P12: 90500 | Q12: =P12/E12 -> 90500 | T12: =AD12*$T$3 -> 0 | U12: =AD12*$U$3 -> 0 | V12: =AD12*$V$3 -> 0 | W12: =AD12*$W$3 -> 0 | X12: 1250 | Y12: =D12*$K$3*S12 -> 0 | Z12: =(D12*S12)+T12+U12+V12+W12+X12+Y12 -> 1250 | AA12: =AB12/AC12 -> #DIV/0! | AB12: =AC12-Z12 -> -1250 | AC12: =AD12/$O$4 -> 0 | AE12: =AD12/S12 -> #DIV/0! | AH12: =AR12*$AH$3 -> 0 | AI12: =AR12*$AI$3 -> 0 | AJ12: =AR12*$AJ$3 -> 0 | AK12: =AR12*$AK$3 -> 0 | AL12: 1250 | AM12: =D12*$AM$3*AG12 -> 0 | AN12: =(D12*AG12)+AH12+AI12+AJ12+AK12+AL12+AM12 -> 1250 | AO12: =AP12/AQ12 -> #DIV/0! | AP12: =AQ12-AN12 -> -1250 | AQ12: =AR12/$O$4 -> 0 | AS12: =AR12/AG12 -> #DIV/0!
A13: CROCKIE GAS BUTANE | B13: ='HPP MALL'!B13 -> 5900 | C13: =B13*$C$4 -> 4838 | D13: =C13/$D$4 -> 4358.5586 | E13: 1 | F13: =P13*$F$3 -> 990 | G13: =P13*$G$3 -> 445.5 | H13: =P13*$H$3 -> 792 | I13: =P13*$I$3 -> 0 | J13: 1250 | K13: =D13*$K$3*E13 -> 305.0991 | L13: =(D13*E13)+F13+G13+H13+I13+J13+K13 -> 8141.1577 | M13: =N13/O13 -> 0.087203535 | N13: =O13-L13 -> 777.76126 | O13: =P13/$O$4 -> 8918.9189 | P13: 9900 | Q13: =P13/E13 -> 9900 | S13: 25 | T13: =AD13*$T$3 -> 18200 | U13: =AD13*$U$3 -> 9100 | V13: =AD13*$V$3 -> 14560 | W13: =AD13*$W$3 -> 0 | X13: 1250 | Y13: =D13*$K$3*S13 -> 7627.4775 | Z13: =(D13*S13)+T13+U13+V13+W13+X13+Y13 -> 159701.44 | AA13: =AB13/AC13 -> 0.025996703 | AB13: =AC13-Z13 -> 4262.5225 | AC13: =AD13/$O$4 -> 163963.96 | AD13: 182000 | AE13: =AD13/S13 -> 7280 | AG13: 300 | AH13: =AR13*$AH$3 -> 245700 | AI13: =AR13*$AI$3 -> 126000 | AJ13: =AR13*$AJ$3 -> 94500 | AK13: =AR13*$AK$3 -> 0 | AL13: 1250 | AM13: =D13*$AM$3*AG13 -> 65378.378 | AN13: =(D13*AG13)+AH13+AI13+AJ13+AK13+AL13+AM13 -> 1840395.9 | AO13: =AP13/AQ13 -> 0.027219286 | AP13: =AQ13-AN13 -> 51495.946 | AQ13: =AR13/$O$4 -> 1891891.9 | AR13: 2100000 | AS13: =AR13/AG13 -> 7000
A14: CROCKIE MAGNET SUPER PLAIN WHITE | B14: ='HPP MALL'!B14 -> 3500 | C14: =B14*$C$4 -> 2870 | D14: =C14/$D$4 -> 2585.5856 | E14: 5 | F14: =P14*$F$3 -> 2500 | G14: =P14*$G$3 -> 1125 | H14: =P14*$H$3 -> 2000 | I14: =P14*$I$3 -> 0 | J14: 1250 | K14: =D14*$K$3*E14 -> 904.95496 | L14: =(D14*E14)+F14+G14+H14+I14+J14+K14 -> 20707.883 | M14: =N14/O14 -> 0.08057 | N14: =O14-L14 -> 1814.6396 | O14: =P14/$O$4 -> 22522.523 | P14: 25000 | Q14: =P14/E14 -> 5000 | S14: 50 | T14: =AD14*$T$3 -> 21300 | U14: =AD14*$U$3 -> 10650 | V14: =AD14*$V$3 -> 17040 | W14: =AD14*$W$3 -> 0 | X14: 1250 | Y14: =D14*$K$3*S14 -> 9049.5495 | Z14: =(D14*S14)+T14+U14+V14+W14+X14+Y14 -> 188568.83 | AA14: =AB14/AC14 -> 0.017317371 | AB14: =AC14-Z14 -> 3323.0631 | AC14: =AD14/$O$4 -> 191891.89 | AD14: 213000 | AE14: =AD14/S14 -> 4260 | AG14: 500 | AH14: =AR14*$AH$3 -> 0 | AI14: =AR14*$AI$3 -> 0 | AJ14: =AR14*$AJ$3 -> 0 | AK14: =AR14*$AK$3 -> 0 | AL14: 1250 | AM14: =D14*$AM$3*AG14 -> 64639.64 | AN14: =(D14*AG14)+AH14+AI14+AJ14+AK14+AL14+AM14 -> 1358682.4 | AO14: =AP14/AQ14 -> #DIV/0! | AP14: =AQ14-AN14 -> -1358682.4 | AQ14: =AR14/$O$4 -> 0 | AS14: =AR14/AG14 -> 0
A15: CROCKIE MAGNET SUPER PLAIN BLACK | B15: ='HPP MALL'!B15 -> 3500 | C15: =B15*$C$4 -> 2870 | D15: =C15/$D$4 -> 2585.5856 | E15: 3 | F15: =P15*$F$3 -> 1590 | G15: =P15*$G$3 -> 715.5 | H15: =P15*$H$3 -> 1272 | I15: =P15*$I$3 -> 0 | J15: 1250 | K15: =D15*$K$3*E15 -> 542.97297 | L15: =(D15*E15)+F15+G15+H15+I15+J15+K15 -> 13127.23 | M15: =N15/O15 -> 0.083570755 | N15: =O15-L15 -> 1197.0946 | O15: =P15/$O$4 -> 14324.324 | P15: 15900 | Q15: =P15/E15 -> 5300 | S15: 50 | T15: =AD15*$T$3 -> 21300 | U15: =AD15*$U$3 -> 10650 | V15: =AD15*$V$3 -> 17040 | W15: =AD15*$W$3 -> 0 | X15: 1250 | Y15: =D15*$K$3*S15 -> 9049.5495 | Z15: =(D15*S15)+T15+U15+V15+W15+X15+Y15 -> 188568.83 | AA15: =AB15/AC15 -> 0.017317371 | AB15: =AC15-Z15 -> 3323.0631 | AC15: =AD15/$O$4 -> 191891.89 | AD15: 213000 | AE15: =AD15/S15 -> 4260 | AG15: 500 | AH15: =AR15*$AH$3 -> 0 | AI15: =AR15*$AI$3 -> 0 | AJ15: =AR15*$AJ$3 -> 0 | AK15: =AR15*$AK$3 -> 0 | AL15: 1250 | AM15: =D15*$AM$3*AG15 -> 64639.64 | AN15: =(D15*AG15)+AH15+AI15+AJ15+AK15+AL15+AM15 -> 1358682.4 | AO15: =AP15/AQ15 -> #DIV/0! | AP15: =AQ15-AN15 -> -1358682.4 | AQ15: =AR15/$O$4 -> 0 | AS15: =AR15/AG15 -> 0
A16: CROCKIE MAGNET CUSTOM PRINT UV | B16: ='HPP MALL'!B16 -> 5500 | C16: =B16*$C$4 -> 4510 | D16: =C16/$D$4 -> 4063.0631 | E16: 1 | F16: =P16*$F$3 -> 1050 | G16: =P16*$G$3 -> 472.5 | H16: =P16*$H$3 -> 840 | I16: =P16*$I$3 -> 0 | J16: 1250 | K16: =D16*$K$3*E16 -> 284.41441 | L16: =(D16*E16)+F16+G16+H16+I16+J16+K16 -> 7959.9775 | M16: =N16/O16 -> 0.15851667 | N16: =O16-L16 -> 1499.482 | O16: =P16/$O$4 -> 9459.4595 | P16: 10500 | Q16: =P16/E16 -> 10500 | S16: 50 | T16: =AD16*$T$3 -> 38000 | U16: =AD16*$U$3 -> 19000 | V16: =AD16*$V$3 -> 30400 | W16: =AD16*$W$3 -> 0 | X16: 1250 | Y16: =D16*$K$3*S16 -> 14220.721 | Z16: =(D16*S16)+T16+U16+V16+W16+X16+Y16 -> 306023.87 | AA16: =AB16/AC16 -> 0.10608816 | AB16: =AC16-Z16 -> 36318.468 | AC16: =AD16/$O$4 -> 342342.34 | AD16: 380000 | AE16: =AD16/S16 -> 7600 | AG16: 500 | AH16: =AR16*$AH$3 -> 0 | AI16: =AR16*$AI$3 -> 0 | AJ16: =AR16*$AJ$3 -> 0 | AK16: =AR16*$AK$3 -> 0 | AL16: 1250 | AM16: =D16*$AM$3*AG16 -> 101576.58 | AN16: =(D16*AG16)+AH16+AI16+AJ16+AK16+AL16+AM16 -> 2134358.1 | AO16: =AP16/AQ16 -> #DIV/0! | AP16: =AQ16-AN16 -> -2134358.1 | AQ16: =AR16/$O$4 -> 0 | AS16: =AR16/AG16 -> 0
A17: CROCKIE SERI FLAG | B17: ='HPP MALL'!B17 -> 3850 | C17: =B17*$C$4 -> 3157 | D17: =C17/$D$4 -> 2844.1441 | E17: 5 | F17: =P17*$F$3 -> 2600 | G17: =P17*$G$3 -> 1170 | H17: =P17*$H$3 -> 2080 | I17: =P17*$I$3 -> 0 | J17: 1250 | K17: =D17*$K$3*E17 -> 995.45045 | L17: =(D17*E17)+F17+G17+H17+I17+J17+K17 -> 22316.171 | M17: =N17/O17 -> 0.047271154 | N17: =O17-L17 -> 1107.2523 | O17: =P17/$O$4 -> 23423.423 | P17: 26000 | Q17: =P17/E17 -> 5200 | S17: 50 | T17: =AD17*$T$3 -> 23900 | U17: =AD17*$U$3 -> 11950 | V17: =AD17*$V$3 -> 19120 | W17: =AD17*$W$3 -> 0 | X17: 1250 | Y17: =D17*$K$3*S17 -> 9954.5045 | Z17: =(D17*S17)+T17+U17+V17+W17+X17+Y17 -> 208381.71 | AA17: =AB17/AC17 -> 0.032202092 | AB17: =AC17-Z17 -> 6933.6036 | AC17: =AD17/$O$4 -> 215315.32 | AD17: 239000 | AE17: =AD17/S17 -> 4780 | AG17: 500 | AH17: =AR17*$AH$3 -> 0 | AI17: =AR17*$AI$3 -> 0 | AJ17: =AR17*$AJ$3 -> 0 | AK17: =AR17*$AK$3 -> 0 | AL17: 1250 | AM17: =D17*$AM$3*AG17 -> 71103.604 | AN17: =(D17*AG17)+AH17+AI17+AJ17+AK17+AL17+AM17 -> 1494425.7 | AO17: =AP17/AQ17 -> #DIV/0! | AP17: =AQ17-AN17 -> -1494425.7 | AQ17: =AR17/$O$4 -> 0 | AS17: =AR17/AG17 -> 0
A18: CROCKIE SERIES | B18: ='HPP MALL'!B18 -> 4350 | C18: =B18*$C$4 -> 3567 | D18: =C18/$D$4 -> 3213.5135 | E18: 5 | F18: =P18*$F$3 -> 3300 | G18: =P18*$G$3 -> 1485 | H18: =P18*$H$3 -> 2640 | I18: =P18*$I$3 -> 0 | J18: 1250 | K18: =D18*$K$3*E18 -> 1124.7297 | L18: =(D18*E18)+F18+G18+H18+I18+J18+K18 -> 25867.297 | M18: =N18/O18 -> 0.12991818 | N18: =O18-L18 -> 3862.4324 | O18: =P18/$O$4 -> 29729.73 | P18: 33000 | Q18: =P18/E18 -> 6600 | S18: 50 | T18: =AD18*$T$3 -> 26900 | U18: =AD18*$U$3 -> 13450 | V18: =AD18*$V$3 -> 21520 | W18: =AD18*$W$3 -> 0 | X18: 1250 | Y18: =D18*$K$3*S18 -> 11247.297 | Z18: =(D18*S18)+T18+U18+V18+W18+X18+Y18 -> 235042.97 | AA18: =AB18/AC18 -> 0.030120074 | AB18: =AC18-Z18 -> 7299.3694 | AC18: =AD18/$O$4 -> 242342.34 | AD18: 269000 | AE18: =AD18/S18 -> 5380 | AG18: 500 | AH18: =AR18*$AH$3 -> 0 | AI18: =AR18*$AI$3 -> 0 | AJ18: =AR18*$AJ$3 -> 0 | AK18: =AR18*$AK$3 -> 0 | AL18: 1250 | AM18: =D18*$AM$3*AG18 -> 80337.838 | AN18: =(D18*AG18)+AH18+AI18+AJ18+AK18+AL18+AM18 -> 1688344.6 | AO18: =AP18/AQ18 -> #DIV/0! | AP18: =AQ18-AN18 -> -1688344.6 | AQ18: =AR18/$O$4 -> 0 | AS18: =AR18/AG18 -> 0
A19: CROCKIE JETFLIP | B19: ='HPP MALL'!B19 -> 49000 | C19: =B19*$C$4 -> 40180 | D19: =C19/$D$4 -> 36198.198 | E19: 1 | F19: =P19*$F$3 -> 6150 | G19: =P19*$G$3 -> 2767.5 | H19: =P19*$H$3 -> 4920 | I19: =P19*$I$3 -> 0 | J19: 1250 | K19: =D19*$K$3*E19 -> 2533.8739 | L19: =(D19*E19)+F19+G19+H19+I19+J19+K19 -> 53819.572 | M19: =N19/O19 -> 0.028622358 | N19: =O19-L19 -> 1585.8333 | O19: =P19/$O$4 -> 55405.405 | P19: 61500 | Q19: =P19/E19 -> 61500 | T19: =AD19*$T$3 -> 0 | U19: =AD19*$U$3 -> 0 | V19: =AD19*$V$3 -> 0 | W19: =AD19*$W$3 -> 0 | X19: 1250 | Y19: =D19*$K$3*S19 -> 0 | Z19: =(D19*S19)+T19+U19+V19+W19+X19+Y19 -> 1250 | AA19: =AB19/AC19 -> #DIV/0! | AB19: =AC19-Z19 -> -1250 | AC19: =AD19/$O$4 -> 0 | AE19: =AD19/S19 -> #DIV/0! | AH19: =AR19*$AH$3 -> 0 | AI19: =AR19*$AI$3 -> 0 | AJ19: =AR19*$AJ$3 -> 0 | AK19: =AR19*$AK$3 -> 0 | AL19: 1250 | AM19: =D19*$AM$3*AG19 -> 0 | AN19: =(D19*AG19)+AH19+AI19+AJ19+AK19+AL19+AM19 -> 1250 | AO19: =AP19/AQ19 -> #DIV/0! | AP19: =AQ19-AN19 -> -1250 | AQ19: =AR19/$O$4 -> 0 | AS19: =AR19/AG19 -> #DIV/0!
A20: CROCKIE JETFLIP + PRINT UV | B20: ='HPP MALL'!B20 -> 51000 | C20: =B20*$C$4 -> 41820 | D20: =C20/$D$4 -> 37675.676 | E20: 1 | F20: =P20*$F$3 -> 6300 | G20: =P20*$G$3 -> 2835 | H20: =P20*$H$3 -> 5040 | I20: =P20*$I$3 -> 0 | J20: 1250 | K20: =D20*$K$3*E20 -> 2637.2973 | L20: =(D20*E20)+F20+G20+H20+I20+J20+K20 -> 55737.973 | M20: =N20/O20 -> 0.01795 | N20: =O20-L20 -> 1018.7838 | O20: =P20/$O$4 -> 56756.757 | P20: 63000 | Q20: =P20/E20 -> 63000
A21: PAKET BUNDLING CROCKIE | AH21: - | AM21: - | AN21: - | AO21: #DIV/0! | AP21: - | AQ21: - | AU21: - | AW21: - | AX21: - | AY21: #DIV/0! | AZ21: - | BA21: -
A22: C. BARA T. 5PCS + GAS B. 1PCS | B22: =B7*5+B13 -> 26400 | C22: =B22*$C$4 -> 21648 | D22: =C22/$D$4 -> 19502.703 | E22: 1 | F22: =P22*$F$3 -> 3300 | G22: =P22*$G$3 -> 1485 | H22: =P22*$H$3 -> 2640 | I22: =P22*$I$3 -> 0 | J22: 1250 | K22: =D22*$K$3*E22 -> 1365.1892 | L22: =(D22*E22)+F22+G22+H22+I22+J22+K22 -> 29542.892 | M22: =N22/O22 -> 0.0062845455 | N22: =O22-L22 -> 186.83784 | O22: =P22/$O$4 -> 29729.73 | P22: 33000 | Q22: =P22/E22 -> 33000 | T22: =AD22*$T$3 -> 0 | U22: =AD22*$U$3 -> 0 | V22: =AD22*$V$3 -> 0 | W22: =AD22*$W$3 -> 0 | X22: 1250 | Y22: =D22*$Y$3*S22 -> 0 | Z22: =(D22*S22)+T22+U22+V22+W22+X22+Y22 -> 1250 | AA22: =AB22/AC22 -> #DIV/0! | AB22: =AC22-Z22 -> -1250 | AC22: =AD22/$O$4 -> 0 | AE22: =AD22/S22 -> #DIV/0! | AH22: =AR22*$AH$3 -> 0 | AI22: =AR22*$AI$3 -> 0 | AJ22: =AR22*$AJ$3 -> 0 | AK22: =AR22*$AK$3 -> 0 | AL22: 1250 | AM22: =AF22*$AM$3 -> 0 | AN22: =(R22*AG22)+AH22+AI22+AJ22+AK22+AL22+AM22 -> 1250 | AO22: =AP22/AQ22 -> #DIV/0! | AP22: =AQ22-AN22 -> -1250 | AQ22: =AR22/$O$4 -> 0 | AS22: =AR22/AG22 -> #DIV/0!
A23: C. BARA T. 5PCS + GAS B. 2PCS | B23: =B7*5+B13*2 -> 32300 | C23: =B23*$C$4 -> 26486 | D23: =C23/$D$4 -> 23861.261 | E23: 1 | F23: =P23*$F$3 -> 4000 | G23: =P23*$G$3 -> 1800 | H23: =P23*$H$3 -> 3200 | I23: =P23*$I$3 -> 0 | J23: 1250 | K23: =D23*$K$3*E23 -> 1670.2883 | L23: =(D23*E23)+F23+G23+H23+I23+J23+K23 -> 35781.55 | M23: =N23/O23 -> 0.007062 | N23: =O23-L23 -> 254.48649 | O23: =P23/$O$4 -> 36036.036 | P23: 40000 | Q23: =P23/E23 -> 40000 | T23: =AD23*$T$3 -> 0 | U23: =AD23*$U$3 -> 0 | V23: =AD23*$V$3 -> 0 | W23: =AD23*$W$3 -> 0 | X23: 1250 | Y23: =D23*$Y$3*S23 -> 0 | Z23: =(D23*S23)+T23+U23+V23+W23+X23+Y23 -> 1250 | AA23: =AB23/AC23 -> #DIV/0! | AB23: =AC23-Z23 -> -1250 | AC23: =AD23/$O$4 -> 0 | AE23: =AD23/S23 -> #DIV/0! | AH23: =AR23*$AH$3 -> 0 | AI23: =AR23*$AI$3 -> 0 | AJ23: =AR23*$AJ$3 -> 0 | AK23: =AR23*$AK$3 -> 0 | AL23: 1250 | AM23: =AF23*$AM$3 -> 0 | AN23: =(R23*AG23)+AH23+AI23+AJ23+AK23+AL23+AM23 -> 1250 | AO23: =AP23/AQ23 -> #DIV/0! | AP23: =AQ23-AN23 -> -1250 | AQ23: =AR23/$O$4 -> 0 | AS23: =AR23/AG23 -> #DIV/0!
A24: C. SUPERJET 1PCS + GAS B. 1PCS | B24: =B8+B13 -> 30900 | C24: =B24*$C$4 -> 25338 | D24: =C24/$D$4 -> 22827.027 | E24: 1 | F24: =P24*$F$3 -> 3950 | G24: =P24*$G$3 -> 1777.5 | H24: =P24*$H$3 -> 3160 | I24: =P24*$I$3 -> 0 | J24: 1250 | K24: =D24*$K$3*E24 -> 1597.8919 | L24: =(D24*E24)+F24+G24+H24+I24+J24+K24 -> 34562.419 | M24: =N24/O24 -> 0.028752278 | N24: =O24-L24 -> 1023.1667 | O24: =P24/$O$4 -> 35585.586 | P24: 39500 | Q24: =P24/E24 -> 39500 | T24: =AD24*$T$3 -> 0 | U24: =AD24*$U$3 -> 0 | V24: =AD24*$V$3 -> 0 | W24: =AD24*$W$3 -> 0 | X24: 1250 | Y24: =D24*$Y$3*S24 -> 0 | Z24: =(D24*S24)+T24+U24+V24+W24+X24+Y24 -> 1250 | AA24: =AB24/AC24 -> #DIV/0! | AB24: =AC24-Z24 -> -1250 | AC24: =AD24/$O$4 -> 0 | AE24: =AD24/S24 -> #DIV/0! | AH24: =AR24*$AH$3 -> 0 | AI24: =AR24*$AI$3 -> 0 | AJ24: =AR24*$AJ$3 -> 0 | AK24: =AR24*$AK$3 -> 0 | AL24: 1250 | AM24: =AF24*$AM$3 -> 0 | AN24: =(R24*AG24)+AH24+AI24+AJ24+AK24+AL24+AM24 -> 1250 | AO24: =AP24/AQ24 -> #DIV/0! | AP24: =AQ24-AN24 -> -1250 | AQ24: =AR24/$O$4 -> 0 | AS24: =AR24/AG24 -> #DIV/0!
A25: C. SUPERJET 2PCS + GAS B. 2PCS | B25: =B8*2+B13*2 -> 61800 | C25: =B25*$C$4 -> 50676 | D25: =C25/$D$4 -> 45654.054 | E25: 1 | F25: =P25*$F$3 -> 7600 | G25: =P25*$G$3 -> 3420 | H25: =P25*$H$3 -> 6080 | I25: =P25*$I$3 -> 0 | J25: 1250 | K25: =D25*$K$3*E25 -> 3195.7838 | L25: =(D25*E25)+F25+G25+H25+I25+J25+K25 -> 67199.838 | M25: =N25/O25 -> 0.018528684 | N25: =O25-L25 -> 1268.6306 | O25: =P25/$O$4 -> 68468.468 | P25: 76000 | Q25: =P25/E25 -> 76000 | Y25: =D25*$Y$3*S25 -> 0
A26: C. SUPERJET 4PCS + GAS B. 1PCS | B26: =B8*4+B13 -> 105900 | C26: =B26*$C$4 -> 86838 | D26: =C26/$D$4 -> 78232.432 | E26: 1 | F26: =P26*$F$3 -> 12650 | G26: =P26*$G$3 -> 5692.5 | H26: =P26*$H$3 -> 10120 | I26: =P26*$I$3 -> 0 | J26: 1250 | K26: =D26*$K$3*E26 -> 5476.2703 | L26: =(D26*E26)+F26+G26+H26+I26+J26+K26 -> 113421.2 | M26: =N26/O26 -> 0.0047625692 | N26: =O26-L26 -> 542.76126 | O26: =P26/$O$4 -> 113963.96 | P26: 126500 | Q26: =P26/E26 -> 126500 | Y26: =D26*$Y$3*S26 -> 0
A27: C. SUPERJET 4PCS + GAS B. 2PCS | B27: =B8*4+B13*2 -> 111800 | C27: =B27*$C$4 -> 91676 | D27: =C27/$D$4 -> 82590.991 | E27: 1 | F27: =P27*$F$3 -> 13320 | G27: =P27*$G$3 -> 5994 | H27: =P27*$H$3 -> 10656 | I27: =P27*$I$3 -> 0 | J27: 1250 | K27: =D27*$K$3*E27 -> 5781.3694 | L27: =(D27*E27)+F27+G27+H27+I27+J27+K27 -> 119592.36 | M27: =N27/O27 -> 0.003396997 | N27: =O27-L27 -> 407.63964 | O27: =P27/$O$4 -> 120000 | P27: 133200 | Q27: =P27/E27 -> 133200 | Y27: =D27*$Y$3*S27 -> 0
K28: =D28*$K$3*E28 -> 0 | Y28: =D28*$Y$3*S28 -> 0
A29: POWERJET 1PCS + GAS B. 1PCS | B29: =B12+B13 -> 78900 | C29: =B29*$C$4 -> 64698 | D29: =C29/$D$4 -> 58286.486 | E29: 1 | F29: =P29*$F$3 -> 9450 | G29: =P29*$G$3 -> 4252.5 | H29: =P29*$H$3 -> 7560 | I29: =P29*$I$3 -> 0 | J29: 1250 | K29: =D29*$K$3*E29 -> 4080.0541 | L29: =(D29*E29)+F29+G29+H29+I29+J29+K29 -> 84879.041 | M29: =N29/O29 -> 0.0030080952 | N29: =O29-L29 -> 256.09459 | O29: =P29/$O$4 -> 85135.135 | P29: 94500 | Q29: =P29/E29 -> 94500 | T29: =AD29*$T$3 -> 0 | U29: =AD29*$U$3 -> 0 | V29: =AD29*$V$3 -> 0 | W29: =AD29*$W$3 -> 0 | X29: 1250 | Y29: =D29*$Y$3*S29 -> 0 | Z29: =(D29*S29)+T29+U29+V29+W29+X29+Y29 -> 1250 | AA29: =AB29/AC29 -> #DIV/0! | AB29: =AC29-Z29 -> -1250 | AC29: =AD29/$O$4 -> 0 | AE29: =AD29/S29 -> #DIV/0! | AH29: =AR29*$AH$3 -> 0 | AI29: =AR29*$AI$3 -> 0 | AJ29: =AR29*$AJ$3 -> 0 | AK29: =AR29*$AK$3 -> 0 | AL29: 1250 | AM29: =AF29*$AM$3 -> 0 | AN29: =(R29*AG29)+AH29+AI29+AJ29+AK29+AL29+AM29 -> 1250 | AO29: =AP29/AQ29 -> #DIV/0! | AP29: =AQ29-AN29 -> -1250 | AQ29: =AR29/$O$4 -> 0 | AS29: =AR29/AG29 -> #DIV/0!
